<robot name="arm_right_testbed">
  <joint name="wrist_right_axis0" type="revolute">
    <parent link="arm_right_lower" />
    <child link="wrist_right_link1" />
    <origin rpy="0  0  0" xyz="0      -0.00449 -0.21" />
    <axis xyz="0 -1  0" />
    <limit effort="0.0" lower="-3.14159265359" upper="3.14159265359" velocity="0.0" />
  </joint>
  <joint name="wrist_right_axis1" type="revolute">
    <parent link="wrist_right_link1" />
    <child link="wrist_right_link2" />
    <origin rpy="0  0  0" xyz="0  0  0" />
    <axis xyz="-0.99974  0      -0.02268" />
    <limit effort="0.0" lower="-3.14159265359" upper="3.14159265359" velocity="0.0" />
  </joint>
  <joint name="wrist_right_axis2" type="revolute">
    <parent link="wrist_right_link2" />
    <child link="hand_right" />
    <origin rpy="0  0  0" xyz="0  0  0" />
    <axis xyz="0.02268  0      -0.99974" />
    <limit effort="0.0" lower="-3.14159265359" upper="3.14159265359" velocity="0.0" />
  </joint>
  <joint name="elbow_right_axis0" type="revolute">
    <parent link="arm_right_upper" />
    <child link="elbow_core_right" />
    <origin rpy="0  0  0" xyz="0       0.00899 -0.3117" />
    <axis xyz="0  1  0" />
    <limit effort="0.0" lower="-1.57079632679" upper="0.0" velocity="0.0" />
  </joint>
  <joint name="elbow_right_axis1" type="revolute">
    <parent link="elbow_core_right" />
    <child link="arm_right_lower" />
    <origin rpy="0  0  0" xyz="0     -0.0015 -0.09" />
    <axis xyz="0  1  0" />
    <limit effort="0.0" lower="-1.57079632679" upper="0.0" velocity="0.0" />
  </joint>
  <joint name="shoulder_right_axis0" type="revolute">
    <parent link="torso" />
    <child link="shoulder_right_link1" />
    <origin rpy="0  0  0" xyz="0  0  0" />
    <axis xyz="0 -1  0" />
    <limit effort="0.0" lower="-3.14159265359" upper="3.14159265359" velocity="0.0" />
  </joint>
  <joint name="shoulder_right_axis1" type="revolute">
    <parent link="shoulder_right_link1" />
    <child link="shoulder_right_link2" />
    <origin rpy="0  0  0" xyz="0  0  0" />
    <axis xyz="-0.99974  0      -0.02268" />
    <limit effort="0.0" lower="-3.14159265359" upper="3.14159265359" velocity="0.0" />
  </joint>
  <joint name="shoulder_right_axis2" type="revolute">
    <parent link="shoulder_right_link2" />
    <child link="arm_right_upper" />
    <origin rpy="0  0  0" xyz="0  0  0" />
    <axis xyz="0.02268  0      -0.99974" />
    <limit effort="0.0" lower="-3.14159265359" upper="3.14159265359" velocity="0.0" />
  </joint>
  <link name="torso">
    <inertial>
      <mass value="5.422363532406723" />
      <origin rpy="0  0  0" xyz="0.00071 -0.12557 -0.06637" />
      <inertia ixx="0.1718373344437835" ixy="-0.0004276859881074785" ixz="0.00022644823054395242" iyy="0.07113673756722771" iyz="-0.053254258427277754" izz="0.12049287805030161" />
    </inertial>
    <collision name="torso_collision">
      <origin rpy="0  0  0" xyz="0.00071 -0.12557 -0.06637" />
      <geometry>
        <mesh filename="package://PATHTOMESHES/meshes/collisions/torso.stl" scale="0.001 0.001 0.001" />
      </geometry>
    </collision>
    <visual name="torso_visual">
      <origin rpy="0  0  0" xyz="0.00071 -0.12557 -0.06637" />
      <geometry>
        <mesh filename="package://PATHTOMESHES/meshes/visuals/torso.stl" scale="0.001 0.001 0.001" />
      </geometry>
    </visual>
  </link>
  <link name="arm_right_upper">
    <inertial>
      <mass value="0.5891162771652175" />
      <origin rpy="0  0  0" xyz="0.00139  0.01353 -0.19639" />
      <inertia ixx="0.030383429832354075" ixy="-1.4268760263931596e-05" ixz="0.00011952446167254048" iyy="0.0310088505990143" iyz="0.0016461207871071" izz="0.0013039639229517261" />
    </inertial>
    <collision name="arm_right_upper_collision">
      <origin rpy="0  0  0" xyz="0.00139  0.01353 -0.19639" />
      <geometry>
        <mesh filename="package://PATHTOMESHES/meshes/collisions/arm_right_upper.stl" scale="0.001 0.001 0.001" />
      </geometry>
    </collision>
    <visual name="arm_right_upper_visual">
      <origin rpy="0  0  0" xyz="0.00139  0.01353 -0.19639" />
      <geometry>
        <mesh filename="package://PATHTOMESHES/meshes/visuals/arm_right_upper.stl" scale="0.001 0.001 0.001" />
      </geometry>
    </visual>
  </link>
  <link name="elbow_core_right">
    <inertial>
      <mass value="0.007877901491278696" />
      <origin rpy="0  0  0" xyz="-0.02706 -0.00503 -0.045" />
      <inertia ixx="0.0010054445915930865" ixy="6.72382888994765e-07" ixz="-7.604777311108837e-05" iyy="0.0010151114823121557" iyz="1.1141539217951613e-05" izz="1.0155477301667562e-05" />
    </inertial>
    <collision name="elbow_core_right_collision">
      <origin rpy="0  0  0" xyz="-0.02706 -0.00503 -0.045" />
      <geometry>
        <mesh filename="package://PATHTOMESHES/meshes/collisions/elbow_core_right.stl" scale="0.001 0.001 0.001" />
      </geometry>
    </collision>
    <visual name="elbow_core_right_visual">
      <origin rpy="0  0  0" xyz="-0.02706 -0.00503 -0.045" />
      <geometry>
        <mesh filename="package://PATHTOMESHES/meshes/visuals/elbow_core_right.stl" scale="0.001 0.001 0.001" />
      </geometry>
    </visual>
  </link>
  <link name="wrist_right_link1">
    <inertial>
      <mass value="0.09036362653441249" />
      <origin rpy="0  0  0" xyz="0  0  0" />
      <inertia ixx="0.033820028122506986" ixy="-1.9094968661814705e-19" ixz="3.905209489118988e-17" iyy="0.033819214849868176" iyz="0.00016582664051215107" izz="7.904867238554277e-06" />
    </inertial>
    <collision name="wrist_right_link1_collision">
      <origin rpy="0  0  0" xyz="0  0  0" />
      <geometry>
        <mesh filename="package://PATHTOMESHES/meshes/collisions/wrist_right_link1.stl" scale="0.001 0.001 0.001" />
      </geometry>
    </collision>
    <visual name="wrist_right_link1_visual">
      <origin rpy="0  0  0" xyz="0  0  0" />
      <geometry>
        <mesh filename="package://PATHTOMESHES/meshes/visuals/wrist_right_link1.stl" scale="0.001 0.001 0.001" />
      </geometry>
    </visual>
  </link>
  <link name="wrist_right_link2">
    <inertial>
      <mass value="0.0071131466390587095" />
      <origin rpy="0  0  0" xyz="0  0  0" />
      <inertia ixx="0.0026617529018687406" ixy="1.1315545639975066e-13" ixz="-2.3072446034971827e-11" iyy="0.0026616888833981512" iyz="1.3053363018819578e-05" izz="1.6655029750509346e-07" />
    </inertial>
    <collision name="wrist_right_link2_collision">
      <origin rpy="0  0  0" xyz="0  0  0" />
      <geometry>
        <mesh filename="package://PATHTOMESHES/meshes/collisions/wrist_right_link2.stl" scale="0.001 0.001 0.001" />
      </geometry>
    </collision>
    <visual name="wrist_right_link2_visual">
      <origin rpy="0  0  0" xyz="0  0  0" />
      <geometry>
        <mesh filename="package://PATHTOMESHES/meshes/visuals/wrist_right_link2.stl" scale="0.001 0.001 0.001" />
      </geometry>
    </visual>
  </link>
  <link name="hand_right">
    <inertial>
      <mass value="0.09241914859474509" />
      <origin rpy="0  0  0" xyz="0.00013 -0.00024 -0.01013" />
      <inertia ixx="0.03575612381751099" ixy="-3.656945748546631e-08" ixz="7.68186721661004e-06" iyy="0.03575627691831428" iyz="0.00015820769968198127" izz="1.2007002176586599e-05" />
    </inertial>
    <collision name="hand_right_collision">
      <origin rpy="0  0  0" xyz="0.00013 -0.00024 -0.01013" />
      <geometry>
        <mesh filename="package://PATHTOMESHES/meshes/collisions/hand_right.stl" scale="0.001 0.001 0.001" />
      </geometry>
    </collision>
    <visual name="hand_right_visual">
      <origin rpy="0  0  0" xyz="0.00013 -0.00024 -0.01013" />
      <geometry>
        <mesh filename="package://PATHTOMESHES/meshes/visuals/hand_right.stl" scale="0.001 0.001 0.001" />
      </geometry>
    </visual>
  </link>
  <link name="arm_right_lower">
    <inertial>
      <mass value="0.7455482248239025" />
      <origin rpy="0  0  0" xyz="0.00116 -0.00515 -0.12785" />
      <inertia ixx="0.2162645339946535" ixy="-1.0198758649085095e-05" ixz="0.0003463582854635617" iyy="0.21616592217058261" iyz="0.0010191114450963672" izz="0.000699232886895972" />
    </inertial>
    <collision name="arm_right_lower_collision">
      <origin rpy="0  0  0" xyz="0.00116 -0.00515 -0.12785" />
      <geometry>
        <mesh filename="package://PATHTOMESHES/meshes/collisions/arm_right_lower.stl" scale="0.001 0.001 0.001" />
      </geometry>
    </collision>
    <visual name="arm_right_lower_visual">
      <origin rpy="0  0  0" xyz="0.00116 -0.00515 -0.12785" />
      <geometry>
        <mesh filename="package://PATHTOMESHES/meshes/visuals/arm_right_lower.stl" scale="0.001 0.001 0.001" />
      </geometry>
    </visual>
  </link>
  <link name="shoulder_right_link1">
    <inertial>
      <mass value="0.09036362653441248" />
      <origin rpy="0  0  0" xyz="0  0  0" />
      <inertia ixx="7.0915945997451785e-06" ixy="4.336808689942018e-23" ixz="1.5929098318157032e-19" iyy="7.091594599745005e-06" iyz="-7.806255641895633e-22" izz="7.0915945997451455e-06" />
    </inertial>
    <collision name="shoulder_right_link1_collision">
      <origin rpy="0  0  0" xyz="0  0  0" />
      <geometry>
        <mesh filename="package://PATHTOMESHES/meshes/collisions/shoulder_right_link1.stl" scale="0.001 0.001 0.001" />
      </geometry>
    </collision>
    <visual name="shoulder_right_link1_visual">
      <origin rpy="0  0  0" xyz="0  0  0" />
      <geometry>
        <mesh filename="package://PATHTOMESHES/meshes/visuals/shoulder_right_link1.stl" scale="0.001 0.001 0.001" />
      </geometry>
    </visual>
  </link>
  <link name="shoulder_right_link2">
    <inertial>
      <mass value="0.0071131466390587095" />
      <origin rpy="0  0  0" xyz="0  0  0" />
      <inertia ixx="1.0253197775360437e-07" ixy="-3.560185740036257e-20" ixz="-5.556536133988211e-23" iyy="1.0253182691604955e-07" iyz="-3.432211119836469e-22" izz="1.0253197775360434e-07" />
    </inertial>
    <collision name="shoulder_right_link2_collision">
      <origin rpy="0  0  0" xyz="0  0  0" />
      <geometry>
        <mesh filename="package://PATHTOMESHES/meshes/collisions/shoulder_right_link2.stl" scale="0.001 0.001 0.001" />
      </geometry>
    </collision>
    <visual name="shoulder_right_link2_visual">
      <origin rpy="0  0  0" xyz="0  0  0" />
      <geometry>
        <mesh filename="package://PATHTOMESHES/meshes/visuals/shoulder_right_link2.stl" scale="0.001 0.001 0.001" />
      </geometry>
    </visual>
  </link>
</robot>