<sdf version="1.6">
	<model name="right_arm">
		<link name="torso">
			<self_collide>false</self_collide>
			<pose frame="">-0.2356613432450572 0.0004095113515327667 -0.05636108580872436 0.0 -0.0 0.0</pose>
			<inertial>
				<pose frame="">0.0 0.0 0.0 0 0 0</pose>
				<mass>14.620248282022308</mass>
				<inertia>
					<ixx>0.23427531359205855</ixx>
					<ixy>0.0014579355491117724</ixy>
					<ixz>-0.19262693759836189</ixz>
					<iyy>1.2900541406140884</iyy>
					<iyz>-0.004143156810960102</iyz>
					<izz>1.1150542050540775</izz>
				</inertia>
			</inertial>
			<collision name="torso_collision">
				<geometry>
					<mesh>
						<uri>model://right_arm/meshes/collisions/torso.stl</uri>
						<scale>0.001 0.001 0.001</scale>
					</mesh>
				</geometry>
			</collision>
			<visual name="torso_visual">
				<geometry>
					<mesh>
						<uri>model://right_arm/meshes/visuals/torso.stl</uri>
						<scale>0.001 0.001 0.001</scale>
					</mesh>
				</geometry>
			</visual>
		</link>
		<link name="upper_arm">
			<self_collide>false</self_collide>
			<pose frame="">-0.4606423102753464 -0.0005403633331535517 -0.21058376160501763 0.0 -0.0 0.0</pose>
			<inertial>
				<pose frame="">0.0 0.0 0.0 0 0 0</pose>
				<mass>1.6107710429284596</mass>
				<inertia>
					<ixx>0.08039547528185673</ixx>
					<ixy>-0.00044122263338615446</ixy>
					<ixz>-0.15603847010888547</ixz>
					<iyy>0.4210036019895847</iyy>
					<iyz>-0.0007419455778243127</iyz>
					<izz>0.3442627310424434</izz>
				</inertia>
			</inertial>
			<collision name="upper_arm_collision">
				<geometry>
					<mesh>
						<uri>model://right_arm/meshes/collisions/upper_arm.stl</uri>
						<scale>0.001 0.001 0.001</scale>
					</mesh>
				</geometry>
			</collision>
			<visual name="upper_arm_visual">
				<geometry>
					<mesh>
						<uri>model://right_arm/meshes/visuals/upper_arm.stl</uri>
						<scale>0.001 0.001 0.001</scale>
					</mesh>
				</geometry>
			</visual>
		</link>
		<link name="elbow">
			<self_collide>false</self_collide>
			<pose frame="">-0.44864256393906743 0.030253483134971674 -0.3553403683418837 0.0 -0.0 0.0</pose>
			<inertial>
				<pose frame="">0.0 0.0 0.0 0 0 0</pose>
				<mass>0.035913480602683824</mass>
				<inertia>
					<ixx>0.004589960085594564</ixx>
					<ixy>0.0004888674766497429</ixy>
					<ixz>-0.00572535532185871</ixz>
					<iyy>0.011778430725057177</iyy>
					<iyz>0.00038601178892672355</iyz>
					<izz>0.007275132898623602</izz>
				</inertia>
			</inertial>
			<collision name="elbow_collision">
				<geometry>
					<mesh>
						<uri>model://right_arm/meshes/collisions/elbow.stl</uri>
						<scale>0.001 0.001 0.001</scale>
					</mesh>
				</geometry>
			</collision>
			<visual name="elbow_visual">
				<geometry>
					<mesh>
						<uri>model://right_arm/meshes/visuals/elbow.stl</uri>
						<scale>0.001 0.001 0.001</scale>
					</mesh>
				</geometry>
			</visual>
		</link>
		<link name="lower_arm">
			<self_collide>false</self_collide>
			<pose frame="">-0.44644014339107224 -0.0027170871429007264 -0.5583060041108712 0.0 -0.0 0.0</pose>
			<inertial>
				<pose frame="">0.0 0.0 0.0 0 0 0</pose>
				<mass>2.0455605412131046</mass>
				<inertia>
					<ixx>0.6621894157798561</ixx>
					<ixy>-0.002530770204603198</ixy>
					<ixz>-0.5091607427935234</ixz>
					<iyy>1.0696876913582016</iyy>
					<iyz>-0.00405789227238752</iyz>
					<izz>0.4093816108713452</izz>
				</inertia>
			</inertial>
			<collision name="lower_arm_collision">
				<geometry>
					<mesh>
						<uri>model://right_arm/meshes/collisions/lower_arm.stl</uri>
						<scale>0.001 0.001 0.001</scale>
					</mesh>
				</geometry>
			</collision>
			<visual name="lower_arm_visual">
				<geometry>
					<mesh>
						<uri>model://right_arm/meshes/visuals/lower_arm.stl</uri>
						<scale>0.001 0.001 0.001</scale>
					</mesh>
				</geometry>
			</visual>
		</link>
		<link name="shoulder_right_link1">
			<self_collide>false</self_collide>
			<pose frame="">-0.4428789810806611 0.000212154754077551 0.00023980058436872886 0.0 -0.0 0.0</pose>
			<inertial>
				<pose frame="">0.0 0.0 0.0 0 0 0</pose>
				<mass>0.09036362653441249</mass>
				<inertia>
					<ixx>7.100858132936025e-06</ixx>
					<ixy>8.490465260946267e-06</ixy>
					<ixz>9.596855559470765e-06</ixz>
					<iyy>0.01773118042040856</iyy>
					<iyz>-4.597234499972153e-09</iyz>
					<izz>0.01773117929134391</izz>
				</inertia>
			</inertial>
			<collision name="shoulder_right_link1_collision">
				<geometry>
					<mesh>
						<uri>model://right_arm/meshes/collisions/shoulder_right_link1.stl</uri>
						<scale>0.001 0.001 0.001</scale>
					</mesh>
				</geometry>
			</collision>
			<visual name="shoulder_right_link1_visual">
				<geometry>
					<mesh>
						<uri>model://right_arm/meshes/visuals/shoulder_right_link1.stl</uri>
						<scale>0.001 0.001 0.001</scale>
					</mesh>
				</geometry>
			</visual>
		</link>
		<link name="shoulder_right_link2">
			<self_collide>false</self_collide>
			<pose frame="">-0.4428789810806621 0.00021215475407754565 0.000239800584367897 0.0 -0.0 0.0</pose>
			<inertial>
				<pose frame="">0.0 0.0 0.0 0 0 0</pose>
				<mass>0.007113171768014984</mass>
				<inertia>
					<ixx>1.0326132814597322e-07</ixx>
					<ixy>6.683456619403606e-07</ixy>
					<ixz>7.554376096350275e-07</ixz>
					<iyy>0.0013952931977171974</iyy>
					<iyz>-3.6188143294127446e-10</iyz>
					<izz>0.0013952931088403884</izz>
				</inertia>
			</inertial>
			<collision name="shoulder_right_link2_collision">
				<geometry>
					<mesh>
						<uri>model://right_arm/meshes/collisions/shoulder_right_link2.stl</uri>
						<scale>0.001 0.001 0.001</scale>
					</mesh>
				</geometry>
			</collision>
			<visual name="shoulder_right_link2_visual">
				<geometry>
					<mesh>
						<uri>model://right_arm/meshes/visuals/shoulder_right_link2.stl</uri>
						<scale>0.001 0.001 0.001</scale>
					</mesh>
				</geometry>
			</visual>
		</link>
		<joint name="elbow_joint_0" type="revolute">
			<parent>upper_arm</parent>
			<child>elbow</child>
			<pose frame="">0.00694256393906727 -0.030253483134971847 0.04363907925784161 0 0 0</pose>
			<axis>
				<xyz>-1.0 6.162975822039155e-33 -3.399077683617213e-33</xyz>
				<limit>
					<lower>0.0</lower>
					<upper>1.0</upper>
				</limit>
				<use_parent_model_frame>0</use_parent_model_frame>
			</axis>
		</joint>
		<joint name="elbow_joint_1" type="revolute">
			<parent>elbow</parent>
			<child>lower_arm</child>
			<pose frame="">0.0029669200863676084 0.002717087142900552 0.15760471502682882 0 0 0</pose>
			<axis>
				<xyz>1.0 -6.162975822039155e-33 -1.1934897514720318e-14</xyz>
				<limit>
					<lower>0.0</lower>
					<upper>1.0</upper>
				</limit>
				<use_parent_model_frame>0</use_parent_model_frame>
			</axis>
		</joint>
		<joint name="shoulder_right_axis0" type="revolute">
			<parent>torso</parent>
			<child>shoulder_right_link1</child>
			<pose frame="">-3.552713678800501e-16 5.063310881681104e-16 9.891393260019755e-17 0 0 0</pose>
			<axis>
				<xyz>0.9743700647852385 2.455559402795019e-15 -0.22495105434386556</xyz>
				<limit>
					<lower>-3.141592653589793</lower>
					<upper>3.141592653589793</upper>
				</limit>
				<use_parent_model_frame>0</use_parent_model_frame>
			</axis>
		</joint>
		<joint name="shoulder_right_axis1" type="revolute">
			<parent>shoulder_right_link1</parent>
			<child>shoulder_right_link2</child>
			<pose frame="">9.947598300641404e-16 2.7026991755718655e-17 7.797928969210943e-16 0 0 0</pose>
			<axis>
				<xyz>1.226605391410805e-15 -1.0000000000000002 9.709926974923143e-16</xyz>
				<limit>
					<lower>-3.141592653589793</lower>
					<upper>3.141592653589793</upper>
				</limit>
				<use_parent_model_frame>0</use_parent_model_frame>
			</axis>
		</joint>
		<joint name="shoulder_right_axis2" type="revolute">
			<parent>shoulder_right_link2</parent>
			<child>upper_arm</child>
			<pose frame="">0.017763329194684232 0.0007525180872311188 0.2108235621893855 0 0 0</pose>
			<axis>
				<xyz>-0.2249510543438651 -5.030698080332758e-16 -0.9743700647852358</xyz>
				<limit>
					<lower>-3.141592653589793</lower>
					<upper>3.141592653589793</upper>
				</limit>
				<use_parent_model_frame>0</use_parent_model_frame>
			</axis>
		</joint>
		<plugin filename="libcardsflow_gazebo_plugin.so" name="cardsflow_gazebo_plugin" />
	</model>
</sdf>