<robot name="roboy_ciie">
  <joint name="zed_camera_mount" type="revolute">
    <parent link="head" />
    <child link="zed_camera" />
    <origin rpy="0  0  0" xyz="0.02168 -0.05805  0.21956" />
    <axis xyz="0  0  0" />
    <limit effort="0" lower="0" upper="0" velocity="0" />
  </joint>
  <joint name="neck_axis0" type="revolute">
    <parent link="torso" />
    <child link="neck_link1" />
    <origin rpy="0  0  0" xyz="0       0.00152  0.71567" />
    <axis xyz="0.12498 -0.99215  0" />
    <limit effort="0.0" lower="-0.523598775598" upper="0.523598775598" velocity="0.0" />
  </joint>
  <joint name="neck_axis2" type="revolute">
    <parent link="neck_link2" />
    <child link="head" />
    <origin rpy="0  0  0" xyz="0  0  0" />
    <axis xyz="0  0  1" />
    <limit effort="0.0" lower="-0.523598775598" upper="0.523598775598" velocity="0.0" />
  </joint>
  <joint name="neck_axis1" type="revolute">
    <parent link="neck_link1" />
    <child link="neck_link2" />
    <origin rpy="0  0  0" xyz="0  0  0" />
    <axis xyz="-0.99215 -0.12498  0" />
    <limit effort="0.0" lower="-0.523598775598" upper="0.523598775598" velocity="0.0" />
  </joint>
  <joint name="zed_camera_right" type="revolute">
    <parent link="zed_camera" />
    <child link="zed_camera_right_lense" />
    <origin rpy="0  0  0" xyz="-0.08149 -0.00191 -0.00782" />
    <axis xyz="0  0  0" />
    <limit effort="0" lower="0" upper="0" velocity="0" />
  </joint>
  <joint name="zed_camera_left" type="revolute">
    <parent link="zed_camera" />
    <child link="zed_camera_left_lense" />
    <origin rpy="0  0  0" xyz="0.03848 -0.00154 -0.00782" />
    <axis xyz="0  0  0" />
    <limit effort="0" lower="0" upper="0" velocity="0" />
  </joint>
  <joint name="elbow_right_axis0" type="revolute">
    <parent link="arm_right_upper" />
    <child link="elbow_core_right" />
    <origin rpy="0  0  0" xyz="1.86000000e-03   2.00000000e-05  -3.13150000e-01" />
    <axis xyz="-0.99863  0.05074 -0.01234" />
    <limit effort="0.0" lower="-1.57079632679" upper="0.0" velocity="0.0" />
  </joint>
  <joint name="elbow_right_axis1" type="revolute">
    <parent link="elbow_core_right" />
    <child link="arm_right_lower" />
    <origin rpy="0  0  0" xyz="2.60000000e-03  -9.00000000e-05  -8.99700000e-02" />
    <axis xyz="-0.99863  0.05074 -0.01234" />
    <limit effort="0.0" lower="-1.57079632679" upper="0.0" velocity="0.0" />
  </joint>
  <joint name="elbow_left_axis0" type="revolute">
    <parent link="arm_left_upper" />
    <child link="elbow_core_left" />
    <origin rpy="0  0  0" xyz="-8.00000000e-05  -4.65000000e-03  -3.09940000e-01" />
    <axis xyz="-0.99863 -0.05074  0.01234" />
    <limit effort="0.0" lower="-3.14159265359" upper="3.14159265359" velocity="0.0" />
  </joint>
  <joint name="elbow_left_axis1" type="revolute">
    <parent link="elbow_core_left" />
    <child link="arm_left_lower" />
    <origin rpy="0  0  0" xyz="-2.60000000e-03  -9.00000000e-05  -8.99700000e-02" />
    <axis xyz="0.99863  0.05074 -0.01234" />
    <limit effort="0.0" lower="-3.14159265359" upper="3.14159265359" velocity="0.0" />
  </joint>
  <joint name="wrist_right_axis0" type="revolute">
    <parent link="arm_right_lower" />
    <child link="wrist_right_link1" />
    <origin rpy="0  0  0" xyz="0.00708 -0.00028 -0.20992" />
    <axis xyz="0.99863 -0.05074  0.01234" />
    <limit effort="0.0" lower="-3.14159265359" upper="3.14159265359" velocity="0.0" />
  </joint>
  <joint name="wrist_right_axis1" type="revolute">
    <parent link="wrist_right_link1" />
    <child link="wrist_right_link2" />
    <origin rpy="0  0  0" xyz="0  0  0" />
    <axis xyz="-0.05045 -0.99846 -0.02306" />
    <limit effort="0.0" lower="-3.14159265359" upper="3.14159265359" velocity="0.0" />
  </joint>
  <joint name="wrist_right_axis2" type="revolute">
    <parent link="wrist_right_link2" />
    <child link="hand_right" />
    <origin rpy="0  0  0" xyz="0  0  0" />
    <axis xyz="0.01349  0.0224  -0.99965" />
    <limit effort="0.0" lower="-3.14159265359" upper="3.14159265359" velocity="0.0" />
  </joint>
  <joint name="wrist_left_axis0" type="revolute">
    <parent link="arm_left_lower" />
    <child link="wrist_left_link1" />
    <origin rpy="0  0  0" xyz="-0.00739 -0.00347 -0.20915" />
    <axis xyz="0.99863 -0.05074  0.01234" />
    <limit effort="0.0" lower="-3.14159265359" upper="3.14159265359" velocity="0.0" />
  </joint>
  <joint name="wrist_left_axis1" type="revolute">
    <parent link="wrist_left_link1" />
    <child link="wrist_left_link2" />
    <origin rpy="0  0  0" xyz="0  0  0" />
    <axis xyz="-0.05045 -0.99846 -0.02306" />
    <limit effort="0.0" lower="-3.14159265359" upper="3.14159265359" velocity="0.0" />
  </joint>
  <joint name="wrist_left_axis2" type="revolute">
    <parent link="wrist_left_link2" />
    <child link="hand_left" />
    <origin rpy="0  0  0" xyz="0  0  0" />
    <axis xyz="0.01349  0.0224  -0.99965" />
    <limit effort="0.0" lower="-3.14159265359" upper="3.14159265359" velocity="0.0" />
  </joint>
  <joint name="shoulder_left_axis0" type="revolute">
    <parent link="torso" />
    <child link="shoulder_left_link1" />
    <origin rpy="0  0  0" xyz="0.29189  0.01393  0.54489" />
    <axis xyz="-0.99863 -0.05074  0.01234" />
    <limit effort="0.0" lower="-3.14159265359" upper="3.14159265359" velocity="0.0" />
  </joint>
  <joint name="shoulder_left_axis1" type="revolute">
    <parent link="shoulder_left_link1" />
    <child link="shoulder_left_link2" />
    <origin rpy="0  0  0" xyz="0  0  0" />
    <axis xyz="-0.05101  0.99844 -0.02231" />
    <limit effort="0.0" lower="-3.14159265359" upper="3.14159265359" velocity="0.0" />
  </joint>
  <joint name="shoulder_left_axis2" type="revolute">
    <parent link="shoulder_left_link2" />
    <child link="arm_left_upper" />
    <origin rpy="0  0  0" xyz="0  0  0" />
    <axis xyz="-0.01118 -0.0229  -0.99967" />
    <limit effort="0.0" lower="-3.14159265359" upper="3.14159265359" velocity="0.0" />
  </joint>
  <joint name="shoulder_right_axis0" type="revolute">
    <parent link="torso" />
    <child link="shoulder_right_link1" />
    <origin rpy="0  0  0" xyz="-0.29317  0.00923  0.5481" />
    <axis xyz="0.99863 -0.05074  0.01234" />
    <limit effort="0.0" lower="-3.14159265359" upper="3.14159265359" velocity="0.0" />
  </joint>
  <joint name="shoulder_right_axis1" type="revolute">
    <parent link="shoulder_right_link1" />
    <child link="shoulder_right_link2" />
    <origin rpy="0  0  0" xyz="0  0  0" />
    <axis xyz="-5.07400000e-02  -9.98710000e-01  -3.70000000e-04" />
    <limit effort="0.0" lower="-3.14159265359" upper="3.14159265359" velocity="0.0" />
  </joint>
  <joint name="shoulder_right_axis2" type="revolute">
    <parent link="shoulder_right_link2" />
    <child link="arm_right_upper" />
    <origin rpy="0  0  0" xyz="0  0  0" />
    <axis xyz="1.23400000e-02  -2.50000000e-04  -9.99920000e-01" />
    <limit effort="0.0" lower="-3.14159265359" upper="3.14159265359" velocity="0.0" />
  </joint>
  <joint name="picoflex" type="revolute">
    <parent link="torso" />
    <child link="picoflex" />
    <origin rpy="0  0  0" xyz="0      -0.10882  0.45109" />
    <axis xyz="0  0  0" />
    <limit effort="0" lower="0" upper="0" velocity="0" />
  </joint>
  <link name="head">
    <inertial>
      <mass value="2.049574035129589" />
      <origin rpy="0  0  0" xyz="0.00051  0.04492  0.14549" />
      <inertia ixx="1.5567369122227759" ixy="-6.313507101682236e-05" ixz="-0.0010119595995300493" iyy="1.5459780882221161" iyz="-0.08466584811454989" izz="0.0305276597273415" />
    </inertial>
    <collision name="head_collision">
      <origin rpy="0  0  0" xyz="0.00051  0.04492  0.14549" />
      <geometry>
        <mesh filename="package://robots/roboy_ciie/meshes/collisions/head.stl" scale="0.001 0.001 0.001" />
      </geometry>
    </collision>
    <visual name="head_visual">
      <origin rpy="0  0  0" xyz="0.00051  0.04492  0.14549" />
      <geometry>
        <mesh filename="package://robots/roboy_ciie/meshes/visuals/head.stl" scale="0.001 0.001 0.001" />
      </geometry>
    </visual>
  </link>
  <link name="torso">
    <inertial>
      <mass value="6.128466296598597" />
      <origin rpy="0  0  0" xyz="0       0.00152  0.29933" />
      <inertia ixx="1.8481384889717514" ixy="-0.0009183207552126455" ixz="0.00317101566132191" iyy="1.990240709546271" iyz="0.006417191930709186" izz="0.17173089640472144" />
    </inertial>
    <collision name="torso_collision">
      <origin rpy="0  0  0" xyz="0       0.00152  0.29933" />
      <geometry>
        <mesh filename="package://robots/roboy_ciie/meshes/collisions/torso.stl" scale="0.001 0.001 0.001" />
      </geometry>
    </collision>
    <visual name="torso_visual">
      <origin rpy="0  0  0" xyz="0       0.00152  0.29933" />
      <geometry>
        <mesh filename="package://robots/roboy_ciie/meshes/visuals/torso.stl" scale="0.001 0.001 0.001" />
      </geometry>
    </visual>
  </link>
  <link name="arm_right_upper">
    <inertial>
      <mass value="0.6350502723994381" />
      <origin rpy="0  0  0" xyz="-0.00667  0.0017  -0.18649" />
      <inertia ixx="0.09221364233694017" ixy="0.0020445951872920948" ixz="0.06908368301826982" iyy="0.14845405747892282" iyz="-0.0025503485567948004" izz="0.058447690439251236" />
    </inertial>
    <collision name="arm_right_upper_collision">
      <origin rpy="0  0  0" xyz="-0.00667  0.0017  -0.18649" />
      <geometry>
        <mesh filename="package://robots/roboy_ciie/meshes/collisions/arm_right_upper.stl" scale="0.001 0.001 0.001" />
      </geometry>
    </collision>
    <visual name="arm_right_upper_visual">
      <origin rpy="0  0  0" xyz="-0.00667  0.0017  -0.18649" />
      <geometry>
        <mesh filename="package://robots/roboy_ciie/meshes/visuals/arm_right_upper.stl" scale="0.001 0.001 0.001" />
      </geometry>
    </visual>
  </link>
  <link name="arm_left_upper">
    <inertial>
      <mass value="0.6332794141190868" />
      <origin rpy="0  0  0" xyz="0.00783 -0.00204 -0.1831" />
      <inertia ixx="0.0920136808059928" ixy="-0.00221866075892502" ixz="-0.06885807577825201" iyy="0.1480342346298382" iyz="-0.0028442817890328275" izz="0.05825497551019246" />
    </inertial>
    <collision name="arm_left_upper_collision">
      <origin rpy="0  0  0" xyz="0.00783 -0.00204 -0.1831" />
      <geometry>
        <mesh filename="package://robots/roboy_ciie/meshes/collisions/arm_left_upper.stl" scale="0.001 0.001 0.001" />
      </geometry>
    </collision>
    <visual name="arm_left_upper_visual">
      <origin rpy="0  0  0" xyz="0.00783 -0.00204 -0.1831" />
      <geometry>
        <mesh filename="package://robots/roboy_ciie/meshes/visuals/arm_left_upper.stl" scale="0.001 0.001 0.001" />
      </geometry>
    </visual>
  </link>
  <link name="shoulder_left_link1">
    <inertial>
      <mass value="0.09036188404972216" />
      <origin rpy="0  0  0" xyz="0  0  0" />
      <inertia ixx="0.02685378687433716" ixy="-0.00036759420957439013" ixz="-0.01437212697441521" iyy="0.03453525279236198" iyz="-0.0006862058794001133" izz="0.0077236593139688075" />
    </inertial>
    <collision name="shoulder_left_link1_collision">
      <origin rpy="0  0  0" xyz="0  0  0" />
      <geometry>
        <mesh filename="package://robots/roboy_ciie/meshes/collisions/shoulder_left_link1.stl" scale="0.001 0.001 0.001" />
      </geometry>
    </collision>
    <visual name="shoulder_left_link1_visual">
      <origin rpy="0  0  0" xyz="0  0  0" />
      <geometry>
        <mesh filename="package://robots/roboy_ciie/meshes/visuals/shoulder_left_link1.stl" scale="0.001 0.001 0.001" />
      </geometry>
    </visual>
  </link>
  <link name="shoulder_left_link2">
    <inertial>
      <mass value="0.00711317010884494" />
      <origin rpy="0  0  0" xyz="0  0  0" />
      <inertia ixx="0.0021134396605301214" ixy="-2.893679789213243e-05" ixz="-0.0011313551510286908" iyy="0.00271811459643765" iyz="-5.401772354685746e-05" izz="0.000607540702812908" />
    </inertial>
    <collision name="shoulder_left_link2_collision">
      <origin rpy="0  0  0" xyz="0  0  0" />
      <geometry>
        <mesh filename="package://robots/roboy_ciie/meshes/collisions/shoulder_left_link2.stl" scale="0.001 0.001 0.001" />
      </geometry>
    </collision>
    <visual name="shoulder_left_link2_visual">
      <origin rpy="0  0  0" xyz="0  0  0" />
      <geometry>
        <mesh filename="package://robots/roboy_ciie/meshes/visuals/shoulder_left_link2.stl" scale="0.001 0.001 0.001" />
      </geometry>
    </visual>
  </link>
  <link name="shoulder_right_link1">
    <inertial>
      <mass value="0.09036760208789225" />
      <origin rpy="0  0  0" xyz="0  0  0" />
      <inertia ixx="0.02716277857038176" ixy="0.00024465659548951447" ixz="0.014521126966952602" iyy="0.03492224741539772" iyz="-0.00045739786268846115" izz="0.0077819738648302085" />
    </inertial>
    <collision name="shoulder_right_link1_collision">
      <origin rpy="0  0  0" xyz="0  0  0" />
      <geometry>
        <mesh filename="package://robots/roboy_ciie/meshes/collisions/shoulder_right_link1.stl" scale="0.001 0.001 0.001" />
      </geometry>
    </collision>
    <visual name="shoulder_right_link1_visual">
      <origin rpy="0  0  0" xyz="0  0  0" />
      <geometry>
        <mesh filename="package://robots/roboy_ciie/meshes/visuals/shoulder_right_link1.stl" scale="0.001 0.001 0.001" />
      </geometry>
    </visual>
  </link>
  <link name="shoulder_right_link2">
    <inertial>
      <mass value="0.007113171768782596" />
      <origin rpy="0  0  0" xyz="0  0  0" />
      <inertia ixx="0.002137629132340016" ixy="1.9257030781476826e-05" ixz="0.0011430126664005362" iyy="0.002748406222637266" iyz="-3.600199406508284e-05" izz="0.0006120927174830887" />
    </inertial>
    <collision name="shoulder_right_link2_collision">
      <origin rpy="0  0  0" xyz="0  0  0" />
      <geometry>
        <mesh filename="package://robots/roboy_ciie/meshes/collisions/shoulder_right_link2.stl" scale="0.001 0.001 0.001" />
      </geometry>
    </collision>
    <visual name="shoulder_right_link2_visual">
      <origin rpy="0  0  0" xyz="0  0  0" />
      <geometry>
        <mesh filename="package://robots/roboy_ciie/meshes/visuals/shoulder_right_link2.stl" scale="0.001 0.001 0.001" />
      </geometry>
    </visual>
  </link>
  <link name="zed_camera_left_lense">
    <inertial>
      <mass value="0.005755421856391891" />
      <origin rpy="0  0  0" xyz="5.00000000e-05  -1.10700000e-02   2.35000000e-03" />
      <inertia ixx="0.005003354055639959" ixy="2.3967379469334976e-05" ixz="-0.0003222735583266803" iyy="0.004996529496255549" iyz="0.000370054972711012" izz="4.878384607433584e-05" />
    </inertial>
    <collision name="zed_camera_left_lense_collision">
      <origin rpy="0  0  0" xyz="5.00000000e-05  -1.10700000e-02   2.35000000e-03" />
      <geometry>
        <mesh filename="package://robots/roboy_ciie/meshes/collisions/zed_camera_left_lense.stl" scale="0.001 0.001 0.001" />
      </geometry>
    </collision>
    <visual name="zed_camera_left_lense_visual">
      <origin rpy="0  0  0" xyz="5.00000000e-05  -1.10700000e-02   2.35000000e-03" />
      <geometry>
        <mesh filename="package://robots/roboy_ciie/meshes/visuals/zed_camera_left_lense.stl" scale="0.001 0.001 0.001" />
      </geometry>
    </visual>
  </link>
  <link name="zed_camera_right_lense">
    <inertial>
      <mass value="0.0057554218551259745" />
      <origin rpy="0  0  0" xyz="3.00000000e-05  -1.10700000e-02   2.35000000e-03" />
      <inertia ixx="0.0050036549322322954" ixy="-2.391821338968771e-05" ixz="0.00031988357548007145" iyy="0.004996221065096928" iyz="0.00037207237543609864" izz="4.877629449989427e-05" />
    </inertial>
    <collision name="zed_camera_right_lense_collision">
      <origin rpy="0  0  0" xyz="3.00000000e-05  -1.10700000e-02   2.35000000e-03" />
      <geometry>
        <mesh filename="package://robots/roboy_ciie/meshes/collisions/zed_camera_right_lense.stl" scale="0.001 0.001 0.001" />
      </geometry>
    </collision>
    <visual name="zed_camera_right_lense_visual">
      <origin rpy="0  0  0" xyz="3.00000000e-05  -1.10700000e-02   2.35000000e-03" />
      <geometry>
        <mesh filename="package://robots/roboy_ciie/meshes/visuals/zed_camera_right_lense.stl" scale="0.001 0.001 0.001" />
      </geometry>
    </visual>
  </link>
  <link name="zed_camera">
    <inertial>
      <mass value="0.009633907989226701" />
      <origin rpy="0  0  0" xyz="-0.01743 -0.0014  -0.00805" />
      <inertia ixx="0.008314802982788687" ixy="2.4365338952166025e-06" ixz="-3.793293439362343e-05" iyy="0.008297308522063661" iyz="0.0005174870196291635" izz="4.725323656366554e-05" />
    </inertial>
    <collision name="zed_camera_collision">
      <origin rpy="0  0  0" xyz="-0.01743 -0.0014  -0.00805" />
      <geometry>
        <mesh filename="package://robots/roboy_ciie/meshes/collisions/zed_camera.stl" scale="0.001 0.001 0.001" />
      </geometry>
    </collision>
    <visual name="zed_camera_visual">
      <origin rpy="0  0  0" xyz="-0.01743 -0.0014  -0.00805" />
      <geometry>
        <mesh filename="package://robots/roboy_ciie/meshes/visuals/zed_camera.stl" scale="0.001 0.001 0.001" />
      </geometry>
    </visual>
  </link>
  <link name="neck_link1">
    <inertial>
      <mass value="0.017038665636260372" />
      <origin rpy="0  0  0" xyz="0  0  0" />
      <inertia ixx="0.008728267843512112" ixy="3.905246324887799e-15" ixz="1.836596576210159e-12" iyy="0.008728228385076956" iyz="-1.855689641317778e-05" izz="1.150229285457388e-06" />
    </inertial>
    <collision name="neck_link1_collision">
      <origin rpy="0  0  0" xyz="0  0  0" />
      <geometry>
        <mesh filename="package://robots/roboy_ciie/meshes/collisions/neck_link1.stl" scale="0.001 0.001 0.001" />
      </geometry>
    </collision>
    <visual name="neck_link1_visual">
      <origin rpy="0  0  0" xyz="0  0  0" />
      <geometry>
        <mesh filename="package://robots/roboy_ciie/meshes/visuals/neck_link1.stl" scale="0.001 0.001 0.001" />
      </geometry>
    </visual>
  </link>
  <link name="neck_link2">
    <inertial>
      <mass value="0.011421521917888835" />
      <origin rpy="0  0  0" xyz="0  0  0" />
      <inertia ixx="0.005850573477666747" ixy="2.21885727293928e-15" ixz="1.0435059226432398e-12" iyy="0.005850547027508899" iyz="-1.243923713466404e-05" izz="5.28219512713884e-07" />
    </inertial>
    <collision name="neck_link2_collision">
      <origin rpy="0  0  0" xyz="0  0  0" />
      <geometry>
        <mesh filename="package://robots/roboy_ciie/meshes/collisions/neck_link2.stl" scale="0.001 0.001 0.001" />
      </geometry>
    </collision>
    <visual name="neck_link2_visual">
      <origin rpy="0  0  0" xyz="0  0  0" />
      <geometry>
        <mesh filename="package://robots/roboy_ciie/meshes/visuals/neck_link2.stl" scale="0.001 0.001 0.001" />
      </geometry>
    </visual>
  </link>
  <link name="elbow_core_right">
    <inertial>
      <mass value="0.03214853806162162" />
      <origin rpy="0  0  0" xyz="0.00468 -0.03403 -0.0445" />
      <inertia ixx="0.001196873204896521" ixy="-0.000228322324529166" ixz="0.0017548831498616344" iyy="0.003814219100444652" iyz="0.00015166432125740181" izz="0.0026700837763339006" />
    </inertial>
    <collision name="elbow_core_right_collision">
      <origin rpy="0  0  0" xyz="0.00468 -0.03403 -0.0445" />
      <geometry>
        <mesh filename="package://robots/roboy_ciie/meshes/collisions/elbow_core_right.stl" scale="0.001 0.001 0.001" />
      </geometry>
    </collision>
    <visual name="elbow_core_right_visual">
      <origin rpy="0  0  0" xyz="0.00468 -0.03403 -0.0445" />
      <geometry>
        <mesh filename="package://robots/roboy_ciie/meshes/visuals/elbow_core_right.stl" scale="0.001 0.001 0.001" />
      </geometry>
    </visual>
  </link>
  <link name="wrist_right_link1">
    <inertial>
      <mass value="0.09036192599068141" />
      <origin rpy="0  0  0" xyz="0  0  0" />
      <inertia ixx="0.0003954489687562632" ixy="0.00022589858163981545" ixz="-0.0016528754676495567" iyy="0.007554478423491989" iyz="5.210359875149888e-05" izz="0.007180363055026062" />
    </inertial>
    <collision name="wrist_right_link1_collision">
      <origin rpy="0  0  0" xyz="0  0  0" />
      <geometry>
        <mesh filename="package://robots/roboy_ciie/meshes/collisions/wrist_right_link1.stl" scale="0.001 0.001 0.001" />
      </geometry>
    </collision>
    <visual name="wrist_right_link1_visual">
      <origin rpy="0  0  0" xyz="0  0  0" />
      <geometry>
        <mesh filename="package://robots/roboy_ciie/meshes/visuals/wrist_right_link1.stl" scale="0.001 0.001 0.001" />
      </geometry>
    </visual>
  </link>
  <link name="wrist_right_link2">
    <inertial>
      <mass value="0.007113170682116013" />
      <origin rpy="0  0  0" xyz="0  0  0" />
      <inertia ixx="3.067349419469193e-05" ixy="1.7782400550560026e-05" ixz="-0.00013011207549461386" iyy="0.0005942223030404189" iyz="4.1015185995117e-06" izz="0.0005647724490085319" />
    </inertial>
    <collision name="wrist_right_link2_collision">
      <origin rpy="0  0  0" xyz="0  0  0" />
      <geometry>
        <mesh filename="package://robots/roboy_ciie/meshes/collisions/wrist_right_link2.stl" scale="0.001 0.001 0.001" />
      </geometry>
    </collision>
    <visual name="wrist_right_link2_visual">
      <origin rpy="0  0  0" xyz="0  0  0" />
      <geometry>
        <mesh filename="package://robots/roboy_ciie/meshes/visuals/wrist_right_link2.stl" scale="0.001 0.001 0.001" />
      </geometry>
    </visual>
  </link>
  <link name="hand_right">
    <inertial>
      <mass value="0.09242209619843374" />
      <origin rpy="0  0  0" xyz="0.00037  0.00011 -0.01013" />
      <inertia ixx="0.0005477870962623535" ixy="0.00023370798306527907" ixz="-0.0019513318219561173" iyy="0.007849581291192599" iyz="6.247635574468294e-05" izz="0.007328896863620957" />
    </inertial>
    <collision name="hand_right_collision">
      <origin rpy="0  0  0" xyz="0.00037  0.00011 -0.01013" />
      <geometry>
        <mesh filename="package://robots/roboy_ciie/meshes/collisions/hand_right.stl" scale="0.001 0.001 0.001" />
      </geometry>
    </collision>
    <visual name="hand_right_visual">
      <origin rpy="0  0  0" xyz="0.00037  0.00011 -0.01013" />
      <geometry>
        <mesh filename="package://robots/roboy_ciie/meshes/visuals/hand_right.stl" scale="0.001 0.001 0.001" />
      </geometry>
    </visual>
  </link>
  <link name="arm_right_lower">
    <inertial>
      <mass value="0.7456034542884313" />
      <origin rpy="0  0  0" xyz="0.00678  0.00086 -0.12778" />
      <inertia ixx="0.007385784373233929" ixy="0.0021215073511854253" ixz="0.0035938973722639076" iyy="0.06665854836850091" iyz="-0.00023801085416001332" izz="0.06002356792310982" />
    </inertial>
    <collision name="arm_right_lower_collision">
      <origin rpy="0  0  0" xyz="0.00678  0.00086 -0.12778" />
      <geometry>
        <mesh filename="package://robots/roboy_ciie/meshes/collisions/arm_right_lower.stl" scale="0.001 0.001 0.001" />
      </geometry>
    </collision>
    <visual name="arm_right_lower_visual">
      <origin rpy="0  0  0" xyz="0.00678  0.00086 -0.12778" />
      <geometry>
        <mesh filename="package://robots/roboy_ciie/meshes/visuals/arm_right_lower.stl" scale="0.001 0.001 0.001" />
      </geometry>
    </visual>
  </link>
  <link name="elbow_core_left">
    <inertial>
      <mass value="0.032148505784848944" />
      <origin rpy="0  0  0" xyz="-0.00468 -0.03403 -0.0445" />
      <inertia ixx="0.001196755733679912" ixy="0.0002284847856475204" ixz="-0.0017578816416368738" iyy="0.0038233500980762508" iyz="0.00015150330144220563" izz="0.002679251025443366" />
    </inertial>
    <collision name="elbow_core_left_collision">
      <origin rpy="0  0  0" xyz="-0.00468 -0.03403 -0.0445" />
      <geometry>
        <mesh filename="package://robots/roboy_ciie/meshes/collisions/elbow_core_left.stl" scale="0.001 0.001 0.001" />
      </geometry>
    </collision>
    <visual name="elbow_core_left_visual">
      <origin rpy="0  0  0" xyz="-0.00468 -0.03403 -0.0445" />
      <geometry>
        <mesh filename="package://robots/roboy_ciie/meshes/visuals/elbow_core_left.stl" scale="0.001 0.001 0.001" />
      </geometry>
    </visual>
  </link>
  <link name="wrist_left_link1">
    <inertial>
      <mass value="0.09036192599068142" />
      <origin rpy="0  0  0" xyz="0  0  0" />
      <inertia ixx="0.0003822702276811054" ixy="-0.00014529137823923166" ixz="0.00163435519221757" iyy="0.007555180537604954" iyz="3.3091220084188984e-05" izz="0.007185885411562052" />
    </inertial>
    <collision name="wrist_left_link1_collision">
      <origin rpy="0  0  0" xyz="0  0  0" />
      <geometry>
        <mesh filename="package://robots/roboy_ciie/meshes/collisions/wrist_left_link1.stl" scale="0.001 0.001 0.001" />
      </geometry>
    </collision>
    <visual name="wrist_left_link1_visual">
      <origin rpy="0  0  0" xyz="0  0  0" />
      <geometry>
        <mesh filename="package://robots/roboy_ciie/meshes/visuals/wrist_left_link1.stl" scale="0.001 0.001 0.001" />
      </geometry>
    </visual>
  </link>
  <link name="wrist_left_link2">
    <inertial>
      <mass value="0.0071131706821160115" />
      <origin rpy="0  0  0" xyz="0  0  0" />
      <inertia ixx="2.9636082014000828e-05" ixy="-1.1437119943066695e-05" ixz="0.00012865429454410324" iyy="0.0005942785371454781" iyz="2.6048898236077723e-06" izz="0.0005652081266750178" />
    </inertial>
    <collision name="wrist_left_link2_collision">
      <origin rpy="0  0  0" xyz="0  0  0" />
      <geometry>
        <mesh filename="package://robots/roboy_ciie/meshes/collisions/wrist_left_link2.stl" scale="0.001 0.001 0.001" />
      </geometry>
    </collision>
    <visual name="wrist_left_link2_visual">
      <origin rpy="0  0  0" xyz="0  0  0" />
      <geometry>
        <mesh filename="package://robots/roboy_ciie/meshes/visuals/wrist_left_link2.stl" scale="0.001 0.001 0.001" />
      </geometry>
    </visual>
  </link>
  <link name="arm_left_lower">
    <inertial>
      <mass value="0.7447067129769246" />
      <origin rpy="0  0  0" xyz="-0.00693 -0.00024 -0.12773" />
      <inertia ixx="0.0073171870986413765" ixy="-0.0018947988625409775" ixz="-0.00360695713576742" iyy="0.0666785690302638" iyz="-0.00029394642688787917" izz="0.060089565117776" />
    </inertial>
    <collision name="arm_left_lower_collision">
      <origin rpy="0  0  0" xyz="-0.00693 -0.00024 -0.12773" />
      <geometry>
        <mesh filename="package://robots/roboy_ciie/meshes/collisions/arm_left_lower.stl" scale="0.001 0.001 0.001" />
      </geometry>
    </collision>
    <visual name="arm_left_lower_visual">
      <origin rpy="0  0  0" xyz="-0.00693 -0.00024 -0.12773" />
      <geometry>
        <mesh filename="package://robots/roboy_ciie/meshes/visuals/arm_left_lower.stl" scale="0.001 0.001 0.001" />
      </geometry>
    </visual>
  </link>
  <link name="hand_left">
    <inertial>
      <mass value="0.09242209988286121" />
      <origin rpy="0  0  0" xyz="-3.00000000e-05   1.95000000e-03  -1.05800000e-02" />
      <inertia ixx="0.0005412372632106754" ixy="-0.00019946332161484414" ixz="0.0019466030036795318" iyy="0.007872232434321757" iyz="5.261811540677135e-05" izz="0.007354366481513941" />
    </inertial>
    <collision name="hand_left_collision">
      <origin rpy="0  0  0" xyz="-3.00000000e-05   1.95000000e-03  -1.05800000e-02" />
      <geometry>
        <mesh filename="package://robots/roboy_ciie/meshes/collisions/hand_left.stl" scale="0.001 0.001 0.001" />
      </geometry>
    </collision>
    <visual name="hand_left_visual">
      <origin rpy="0  0  0" xyz="-3.00000000e-05   1.95000000e-03  -1.05800000e-02" />
      <geometry>
        <mesh filename="package://robots/roboy_ciie/meshes/visuals/hand_left.stl" scale="0.001 0.001 0.001" />
      </geometry>
    </visual>
  </link>
  <link name="picoflex">
    <inertial>
      <mass value="0.033034548710557006" />
      <origin rpy="0  0  0" xyz="0.00792  0.00285 -0.06995" />
      <inertia ixx="0.005143475491789387" ixy="5.7494898972426545e-06" ixz="-2.127849382435788e-05" iyy="0.00481125761048844" iyz="0.001286203736409069" izz="0.00035784256110939883" />
    </inertial>
    <collision name="picoflex_collision">
      <origin rpy="0  0  0" xyz="0.00792  0.00285 -0.06995" />
      <geometry>
        <mesh filename="package://robots/roboy_ciie/meshes/collisions/picoflex.stl" scale="0.001 0.001 0.001" />
      </geometry>
    </collision>
    <visual name="picoflex_visual">
      <origin rpy="0  0  0" xyz="0.00792  0.00285 -0.06995" />
      <geometry>
        <mesh filename="package://robots/roboy_ciie/meshes/visuals/picoflex.stl" scale="0.001 0.001 0.001" />
      </geometry>
    </visual>
  </link>
</robot>