<?xml version="1.0" ?>
<!-- =================================================================================== -->
<!-- |    This document was autogenerated by xacro from robody.urdf.xacro              | -->
<!-- |    EDITING THIS FILE BY HAND IS NOT RECOMMENDED                                 | -->
<!-- =================================================================================== -->
<robot name="robody">
  <!-- Used for fixing robot -->
  <link name="world"/>
  <gazebo reference="world">
    <static>true</static>
  </gazebo>
  <joint name="torso_world_joint" type="fixed">
    <origin rpy="0 0 0" xyz="0 0 0"/>
    <parent link="world"/>
    <child link="torso"/>
  </joint>
  <joint name="shoulder_left_axis0" type="revolute">
    <parent link="torso"/>
    <child link="shoulder_left_link1"/>
    <origin rpy="0 0 0" xyz="2.0980e-01 -2.9000e-04  4.8503e-01"/>
    <axis xyz="1  0  0"/>
    <limit effort="1.0" lower="-1.3" upper="0.3" velocity="10.0"/>
  </joint>
  <joint name="shoulder_left_axis1" type="revolute">
    <parent link="shoulder_left_link1"/>
    <child link="shoulder_left_link2"/>
    <origin rpy="0 0 0" xyz="0 0 0"/>
    <axis xyz="0 1  0"/>
    <limit effort="0.0" lower="-1.2" upper="1.0" velocity="0.0"/>
  </joint>
  <joint name="shoulder_left_axis2" type="revolute">
    <parent link="shoulder_left_link2"/>
    <child link="upperarm_left"/>
    <origin rpy="0 0 0" xyz="0   -0.02  0"/>
    <axis xyz="0 0 1"/>
    <limit effort="1.0" lower="-0.3" upper="0.3" velocity="10.0"/>
  </joint>
  <joint name="elbow_left_axis0" type="revolute">
    <parent link="upperarm_left"/>
    <child link="elbow_left"/>
    <origin rpy="0 0 0" xyz="0.012   0.02   -0.3167"/>
    <axis xyz="-1 0 0"/>
    <limit effort="1.0" lower="0.0" upper="0.9" velocity="10.0"/>
  </joint>
  <joint name="elbow_left_axis1" type="revolute">
    <parent link="elbow_left"/>
    <child link="lowerarm_left"/>
    <origin rpy="0 0 0" xyz="-0.003  0    -0.09"/>
    <axis xyz="-1  0  0"/>
    <limit effort="1.0" lower="0.0" upper="0.73" velocity="10.0"/>
  </joint>
 <joint name="wrist_left_axis0" type="revolute">
    <parent link="lowerarm_left" />
    <child link="wrist_left_link1" />
    <origin rpy="0 0 0" xyz="-0.00073  0      -0.21039" />
    <axis xyz="1 0 0" />
    <limit effort="1.0" lower="0.0" upper="0.0" velocity="10.0" />
  </joint>
  <joint name="wrist_left_axis1" type="revolute">
    <parent link="wrist_left_link1" />
    <child link="wrist_left_link2" />
    <origin rpy="0 0 0" xyz="0 0 0" />
    <axis xyz="0 1 0" />
    <limit effort="1.0" lower="0.0" upper="0.0" velocity="10.0" />
  </joint>
  <joint name="wrist_left_axis2" type="revolute">
    <parent link="wrist_left_link2" />
    <child link="hand_left" />
    <origin rpy="0 0 0" xyz="0 0 0" />
    <axis xyz="0 0 1" />
    <limit effort="1.0" lower="0.0" upper="0.0" velocity="10.0" />
  </joint>
  <joint name="head_axis0" type="revolute">
    <parent link="torso"/>
    <child link="head_link1"/>
    <origin rpy="0 0 0" xyz="0      0      0.62575"/>
    <axis xyz="1 0 0"/>
    <limit effort="1.0" lower="-0.6" upper="0.6" velocity="10.0"/>
  </joint>
  <joint name="head_axis1" type="revolute">
    <parent link="head_link1"/>
    <child link="head_link2"/>
    <origin rpy="0 0 0" xyz="0 0 0"/>
    <axis xyz="0  0 -1"/>
    <limit effort="1.0" lower="-0.56" upper="0.56" velocity="10.0"/>
  </joint>
  <joint name="head_axis2" type="revolute">
    <parent link="head_link2"/>
    <child link="head"/>
    <origin rpy="0 0 0" xyz="0.e+00 -2.e-02 -5.e-05"/>
    <axis xyz="0 1 0"/>
    <limit effort="1.0" lower="-0.6" upper="0.6" velocity="10.0"/>
  </joint>
  <joint name="shoulder_right_axis0" type="revolute">
    <parent link="torso"/>
    <child link="shoulder_right_link1"/>
    <origin rpy="0 0 0" xyz="-2.0980e-01 -2.9000e-04  4.8503e-01"/>
    <axis xyz="1 0 0"/>
    <limit effort="1.0" lower="-1.0" upper="0.3" velocity="10.0"/>
  </joint>
  <joint name="shoulder_right_axis1" type="revolute">
    <parent link="shoulder_right_link1"/>
    <child link="shoulder_right_link2"/>
    <origin rpy="0 0 0" xyz="0 0 0"/>
    <axis xyz="0 -1 0"/>
    <limit effort="1.0" lower="-1.2" upper="0.0" velocity="10.0"/>
  </joint>
  <joint name="shoulder_right_axis2" type="revolute">
    <parent link="shoulder_right_link2"/>
    <child link="upperarm_right"/>
    <origin rpy="0 0 0" xyz="0   -0.02  0"/>
    <axis xyz="0 0 -1"/>
    <limit effort="0.0" lower="-0.3" upper="0.3" velocity="0.0"/>
  </joint>
  <joint name="elbow_right_axis0" type="revolute">
    <parent link="upperarm_right"/>
    <child link="elbow_right"/>
    <origin rpy="0 0 0" xyz="-0.012   0.02   -0.3167"/>
    <axis xyz="-1 0 0"/>
    <limit effort="1.0" lower="0.0" upper="0.9" velocity="10.0"/>
  </joint>
  <joint name="elbow_right_axis1" type="revolute">
    <parent link="elbow_right"/>
    <child link="lowerarm_right"/>
    <origin rpy="0 0 0" xyz="0.003  0    -0.09"/>
    <axis xyz="-1  0  0"/>
    <limit effort="1.0" lower="0.0" upper="0.73" velocity="10.0"/>
  </joint>
  <joint name="wrist_right_axis0" type="revolute">
    <parent link="lowerarm_right" />
    <child link="wrist_right_link1" />
    <origin rpy="0 0 0" xyz="-0.00616  0      -0.21039" />
    <axis xyz="1 0 0" />
    <limit effort="1.0" lower="0.0" upper="0.0" velocity="10.0" />
  </joint>
  <joint name="wrist_right_axis1" type="revolute">
    <parent link="wrist_right_link1" />
    <child link="wrist_right_link2" />
    <origin rpy="0 0 0" xyz="0 0 0" />
    <axis xyz="0 -1  0" />
    <limit effort="1.0" lower="0.0" upper="0.0" velocity="10.0" />
  </joint>
  <joint name="wrist_right_axis2" type="revolute">
    <parent link="wrist_right_link2" />
    <child link="hand_right" />
    <origin rpy="0 0 0" xyz="0 0 0" />
    <axis xyz="0  0 -1" />
    <limit effort="1.0" lower="0.0" upper="0.0" velocity="10.0" />
  </joint>

  <link name="torso">
    <inertial>
      <mass value="25.484532049638535"/>
      <origin rpy="0 0 0" xyz="2.3000e-04 1.0600e-02 4.3137e-01"/>
      <inertia ixx="5.258835582254277" ixy="0.00011709544750634677" ixz="-0.00334802333308169" iyy="5.467803837169585" iyz="-0.12072489827759955" izz="0.533803340431137"/>
    </inertial>
    <collision name="torso_collision">
      <origin rpy="0 0 0" xyz="2.3000e-04 1.0600e-02 4.3137e-01"/>
      <geometry>
        <mesh filename="package://ros2_control_upper_body/meshes/CAD/torso.stl" scale="0.001 0.001 0.001"/>
      </geometry>
    </collision>
    <visual name="torso_visual">
      <origin rpy="0 0 0" xyz="2.3000e-04 1.0600e-02 4.3137e-01"/>
      <geometry>
        <mesh filename="package://ros2_control_upper_body/meshes/CAD/torso.stl" scale="0.001 0.001 0.001"/>
      </geometry>
    </visual>
  </link>
  <link name="hand_right">
    <inertial>
      <mass value="0.7514923831884623" />
      <origin rpy="0 0 0" xyz="-0.00506  0.00106 -0.06163" />
      <inertia ixx="0.00329642178906037" ixy="0.0002152027426110002" ixz="0.00414519741777471" iyy="0.040151355516369454" iyz="5.779025691769195e-06" izz="0.03751229870240237" />
    </inertial>
    <collision name="hand_right_collision">
      <origin rpy="0 0 0" xyz="-0.00506  0.00106 -0.06163" />
      <geometry>
        <sphere radius="0.01"/> 
        <!-- TODO -->
        <!-- <mesh filename="package://ros2_control_upper_body/meshes/collisions/hand_right.stl" scale="0.001 0.001 0.001" /> -->
      </geometry>
    </collision>
    <visual name="hand_right_visual">
      <origin rpy="0 0 0" xyz="-0.00506  0.00106 -0.06163" />
      <geometry>
        <sphere radius="0.01"/>
        <!-- TODO -->
        <!-- <mesh filename="package://ros2_control_upper_body/meshes/visuals/hand_right.stl" scale="0.001 0.001 0.001" /> -->
      </geometry>
    </visual>
  </link>
  <link name="lowerarm_right">
    <inertial>
      <mass value="1.0074638997705314"/>
      <origin rpy="0 0 0" xyz="-0.0004  -0.00091 -0.21276"/>
      <inertia ixx="0.03147609850046257" ixy="-0.0002711089785375398" ixz="-0.029796901932204578" iyy="0.0797708396876748" iyz="-6.28652323063764e-05" izz="0.04941236986443757"/>
    </inertial>
    <collision name="lowerarm_right_collision">
      <origin rpy="0 0 0" xyz="-0.0004  -0.00091 -0.21276"/>
      <geometry>
        <mesh filename="package://ros2_control_upper_body/meshes/CAD/lowerarm_right.stl" scale="0.001 0.001 0.001"/>
      </geometry>
    </collision>
    <visual name="lowerarm_right_visual">
      <origin rpy="0 0 0" xyz="-0.0004  -0.00091 -0.21276"/>
      <geometry>
        <mesh filename="package://ros2_control_upper_body/meshes/CAD/lowerarm_right.stl" scale="0.001 0.001 0.001"/>
      </geometry>
    </visual>
  </link>
  <link name="lowerarm_left">
    <inertial>
      <mass value="1.0074631712298445"/>
      <origin rpy="0 0 0" xyz="0.0004  -0.00091 -0.21276"/>
      <inertia ixx="0.03147609940082702" ixy="0.0002711063342370113" ixz="0.029796916712719362" iyy="0.07977080588923677" iyz="-6.286623892047672e-05" izz="0.04941233306547431"/>
    </inertial>
    <collision name="lowerarm_left_collision">
      <origin rpy="0 0 0" xyz="0.0004  -0.00091 -0.21276"/>
      <geometry>
        <mesh filename="package://ros2_control_upper_body/meshes/CAD/lowerarm_left.stl" scale="0.001 0.001 0.001"/>
      </geometry>
    </collision>
    <visual name="lowerarm_left_visual">
      <origin rpy="0 0 0" xyz="0.0004  -0.00091 -0.21276"/>
      <geometry>
        <mesh filename="package://ros2_control_upper_body/meshes/CAD/lowerarm_left.stl" scale="0.001 0.001 0.001"/>
      </geometry>
    </visual>
  </link>
  <link name="hand_left">
    <inertial>
      <mass value="0.7514925489985023" />
      <origin rpy="0 0 0" xyz="0.00506  0.00106 -0.06163" />
      <inertia ixx="0.003296422481405665" ixy="-0.000215224109805972" ixz="-0.004145710073447077" iyy="0.0401603001987594" iyz="5.779043768172425e-06" izz="0.03752124270591726" />
    </inertial>
    <collision name="hand_left_collision">
      <origin rpy="0 0 0" xyz="0.00506  0.00106 -0.06163" />
      <geometry>
        <sphere radius="0.01"/> <!-- <mesh filename="package://ros2_control_upper_body/meshes/collisions/hand_left.stl" scale="0.001 0.001 0.001" /> -->
      </geometry>
    </collision>
    <visual name="hand_left_visual">
      <origin rpy="0 0 0" xyz="0.00506  0.00106 -0.06163" />
      <geometry>
        <sphere radius="0.01"/> <!-- <mesh filename="package://ros2_control_upper_body/meshes/visuals/hand_left.stl" scale="0.001 0.001 0.001" /> -->
      </geometry>
    </visual>
  </link>
  <link name="head">
    <inertial>
      <mass value="33.92015199425921"/>
      <origin rpy="0 0 0" xyz="7.0000e-05 2.6850e-02 1.6837e-01"/>
      <inertia ixx="21.75510812168486" ixy="-0.0005606665168605437" ixz="-0.002267135508357556" iyy="21.69663072025339" iyz="-0.2092129833464968" izz="0.32740001700442967"/>
    </inertial>
    <collision name="head_collision">
      <origin rpy="0 0 0" xyz="7.0000e-05 2.6850e-02 1.6837e-01"/>
      <geometry>
        <mesh filename="package://ros2_control_upper_body/meshes/CAD/head.stl" scale="0.001 0.001 0.001"/>
      </geometry>
    </collision>
    <visual name="head_visual">
      <origin rpy="0 0 0" xyz="7.0000e-05 2.6850e-02 1.6837e-01"/>
      <geometry>
        <mesh filename="package://ros2_control_upper_body/meshes/CAD/head.stl" scale="0.001 0.001 0.001"/>
      </geometry>
    </visual>
  </link>
  <link name="elbow_right">
    <inertial>
      <mass value="0.027833326423345923"/>
      <origin rpy="0 0 0" xyz="0.00488  0.03745 -0.04449"/>
      <inertia ixx="0.00046936798100956297" ixy="0.0002242971847618781" ixz="0.0007476129489564115" iyy="0.0017407566471222783" iyz="-0.00012795789058165995" izz="0.001353174770056334"/>
    </inertial>
    <collision name="elbow_right_collision">
      <origin rpy="0 0 0" xyz="0.00488  0.03745 -0.04449"/>
      <geometry>
        <mesh filename="package://ros2_control_upper_body/meshes/CAD/elbow_right.stl" scale="0.001 0.001 0.001"/>
      </geometry>
    </collision>
    <visual name="elbow_right_visual">
      <origin rpy="0 0 0" xyz="0.00488  0.03745 -0.04449"/>
      <geometry>
        <mesh filename="package://ros2_control_upper_body/meshes/CAD/elbow_right.stl" scale="0.001 0.001 0.001"/>
      </geometry>
    </visual>
  </link>
  <link name="upperarm_right">
    <inertial>
      <mass value="0.47897938041859955"/>
      <origin rpy="0 0 0" xyz="-0.01122  0.02178 -0.18886"/>
      <inertia ixx="0.047739785217205295" ixy="0.0001599943964407516" ixz="0.03134774036779062" iyy="0.07049498506434859" iyz="-0.00020946246956613274" izz="0.024477263936243224"/>
    </inertial>
    <collision name="upperarm_right_collision">
      <origin rpy="0 0 0" xyz="-0.01122  0.02178 -0.18886"/>
      <geometry>
        <mesh filename="package://ros2_control_upper_body/meshes/CAD/upperarm_right.stl" scale="0.001 0.001 0.001"/>
      </geometry>
    </collision>
    <visual name="upperarm_right_visual">
      <origin rpy="0 0 0" xyz="-0.01122  0.02178 -0.18886"/>
      <geometry>
        <mesh filename="package://ros2_control_upper_body/meshes/CAD/upperarm_right.stl" scale="0.001 0.001 0.001"/>
      </geometry>
    </visual>
  </link>
  <link name="shoulder_right_link1">
    <inertial>
      <mass value="0.13152801243029266"/>
      <origin rpy="0 0 0" xyz="0.00375  0.0075  -0.00375"/>
      <inertia ixx="0.030485104811193924" ixy="0.00019548246589014734" ixz="0.013041807175836773" iyy="0.03606823247246791" iyz="-0.000456127340257625" izz="0.00560301206595923"/>
    </inertial>
    <collision name="shoulder_right_link1_collision">
      <origin rpy="0 0 0" xyz="0.00375  0.0075  -0.00375"/>
      <geometry>
        <mesh filename="package://ros2_control_upper_body/meshes/CAD/shoulder_right_link1.stl" scale="0.001 0.001 0.001"/>
      </geometry>
    </collision>
    <visual name="shoulder_right_link1_visual">
      <origin rpy="0 0 0" xyz="0.00375  0.0075  -0.00375"/>
      <geometry>
        <mesh filename="package://ros2_control_upper_body/meshes/CAD/shoulder_right_link1.stl" scale="0.001 0.001 0.001"/>
      </geometry>
    </visual>
  </link>
  <link name="shoulder_right_link2">
    <inertial>
      <mass value="0.1315280124302925"/>
      <origin rpy="0 0 0" xyz="-0.00375 -0.0075  -0.00375"/>
      <inertia ixx="0.030486288563549433" ixy="-0.0002187381219558529" ixz="0.013520274580510552" iyy="0.036482157122224974" iyz="0.0004941088024231829" izz="0.006018120468071959"/>
    </inertial>
    <collision name="shoulder_right_link2_collision">
      <origin rpy="0 0 0" xyz="-0.00375 -0.0075  -0.00375"/>
      <geometry>
        <mesh filename="package://ros2_control_upper_body/meshes/CAD/shoulder_right_link2.stl" scale="0.001 0.001 0.001"/>
      </geometry>
    </collision>
    <visual name="shoulder_right_link2_visual">
      <origin rpy="0 0 0" xyz="-0.00375 -0.0075  -0.00375"/>
      <geometry>
        <mesh filename="package://ros2_control_upper_body/meshes/CAD/shoulder_right_link2.stl" scale="0.001 0.001 0.001"/>
      </geometry>
    </visual>
  </link>
  <link name="elbow_left">
    <inertial>
      <mass value="0.027833366422315858"/>
      <origin rpy="0 0 0" xyz="-0.00488  0.03745 -0.04449"/>
      <inertia ixx="0.000469368745299957" ixy="-0.00022429711641259515" ixz="-0.0007476143495157416" iyy="0.0017407597298930942" iyz="-0.0001279578522344028" izz="0.0013531769418158295"/>
    </inertial>
    <collision name="elbow_left_collision">
      <origin rpy="0 0 0" xyz="-0.00488  0.03745 -0.04449"/>
      <geometry>
        <mesh filename="package://ros2_control_upper_body/meshes/CAD/elbow_left.stl" scale="0.001 0.001 0.001"/>
      </geometry>
    </collision>
    <visual name="elbow_left_visual">
      <origin rpy="0 0 0" xyz="-0.00488  0.03745 -0.04449"/>
      <geometry>
        <mesh filename="package://ros2_control_upper_body/meshes/CAD/elbow_left.stl" scale="0.001 0.001 0.001"/>
      </geometry>
    </visual>
  </link>
  <link name="upperarm_left">
    <inertial>
      <mass value="0.4789794871685731"/>
      <origin rpy="0 0 0" xyz="0.01122  0.02178 -0.18886"/>
      <inertia ixx="0.047739844645411804" ixy="-0.00015998892477739812" ixz="-0.031347771480737675" iyy="0.07049505412035494" iyz="-0.00020945579244281882" izz="0.02447727369058352"/>
    </inertial>
    <collision name="upperarm_left_collision">
      <origin rpy="0 0 0" xyz="0.01122  0.02178 -0.18886"/>
      <geometry>
        <mesh filename="package://ros2_control_upper_body/meshes/CAD/upperarm_left.stl" scale="0.001 0.001 0.001"/>
      </geometry>
    </collision>
    <visual name="upperarm_left_visual">
      <origin rpy="0 0 0" xyz="0.01122  0.02178 -0.18886"/>
      <geometry>
        <mesh filename="package://ros2_control_upper_body/meshes/CAD/upperarm_left.stl" scale="0.001 0.001 0.001"/>
      </geometry>
    </visual>
  </link>
  <link name="shoulder_left_link1">
    <inertial>
      <mass value="0.13152801243029272"/>
      <origin rpy="0 0 0" xyz="-0.00375  0.0075  -0.00375"/>
      <inertia ixx="0.030485104811193892" ixy="-0.00019548246589014729" ixz="-0.013041807175836828" iyy="0.03606823247246791" iyz="-0.000456127340257625" izz="0.0056030120659592755"/>
    </inertial>
    <collision name="shoulder_left_link1_collision">
      <origin rpy="0 0 0" xyz="-0.00375  0.0075  -0.00375"/>
      <geometry>
        <mesh filename="package://ros2_control_upper_body/meshes/CAD/shoulder_left_link1.stl" scale="0.001 0.001 0.001"/>
      </geometry>
    </collision>
    <visual name="shoulder_left_link1_visual">
      <origin rpy="0 0 0" xyz="-0.00375  0.0075  -0.00375"/>
      <geometry>
        <mesh filename="package://ros2_control_upper_body/meshes/CAD/shoulder_left_link1.stl" scale="0.001 0.001 0.001"/>
      </geometry>
    </visual>
  </link>
  <link name="shoulder_left_link2">
    <inertial>
      <mass value="0.13152801243029277"/>
      <origin rpy="0 0 0" xyz="0.00375 -0.0075  -0.00375"/>
      <inertia ixx="0.03048628856354949" ixy="0.00021873812195585343" ixz="-0.013520274580510562" iyy="0.03648215712222504" iyz="0.0004941088024231848" izz="0.00601812046807196"/>
    </inertial>
    <collision name="shoulder_left_link2_collision">
      <origin rpy="0 0 0" xyz="0.00375 -0.0075  -0.00375"/>
      <geometry>
        <mesh filename="package://ros2_control_upper_body/meshes/CAD/shoulder_left_link2.stl" scale="0.001 0.001 0.001"/>
      </geometry>
    </collision>
    <visual name="shoulder_left_link2_visual">
      <origin rpy="0 0 0" xyz="0.00375 -0.0075  -0.00375"/>
      <geometry>
        <mesh filename="package://ros2_control_upper_body/meshes/CAD/shoulder_left_link2.stl" scale="0.001 0.001 0.001"/>
      </geometry>
    </visual>
  </link>
  <link name="head_link1">
    <inertial>
      <mass value="0.13152839994763724"/>
      <origin rpy="0 0 0" xyz="0.00375  0.00751 -0.00372"/>
      <inertia ixx="0.05090880856889025" ixy="-3.349320812476213e-06" ixz="-0.00030864786125929506" iyy="0.05090879019898153" iyz="-0.0006147722468252338" izz="2.106285190859084e-05"/>
    </inertial>
    <collision name="head_link1_collision">
      <origin rpy="0 0 0" xyz="0.00375  0.00751 -0.00372"/>
      <geometry>
        <mesh filename="package://ros2_control_upper_body/meshes/CAD/head_link1.stl" scale="0.001 0.001 0.001"/>
      </geometry>
    </collision>
    <visual name="head_link1_visual">
      <origin rpy="0 0 0" xyz="0.00375  0.00751 -0.00372"/>
      <geometry>
        <mesh filename="package://ros2_control_upper_body/meshes/CAD/head_link1.stl" scale="0.001 0.001 0.001"/>
      </geometry>
    </visual>
  </link>
  <link name="head_link2">
    <inertial>
      <mass value="0.1315280124294498"/>
      <origin rpy="0 0 0" xyz="-0.00375 -0.00749 -0.00377"/>
      <inertia ixx="0.05090190469684626" ixy="-3.3493208073071583e-06" ixz="0.0003086295420776442" iyy="0.0509019230150866" iyz="0.0006130818021459909" izz="2.1026163738168032e-05"/>
    </inertial>
    <collision name="head_link2_collision">
      <origin rpy="0 0 0" xyz="-0.00375 -0.00749 -0.00377"/>
      <geometry>
        <mesh filename="package://ros2_control_upper_body/meshes/CAD/head_link2.stl" scale="0.001 0.001 0.001"/>
      </geometry>
    </collision>
    <visual name="head_link2_visual">
      <origin rpy="0 0 0" xyz="-0.00375 -0.00749 -0.00377"/>
      <geometry>
        <mesh filename="package://ros2_control_upper_body/meshes/CAD/head_link2.stl" scale="0.001 0.001 0.001"/>
      </geometry>
    </visual>
  </link>
  <link name="wrist_left_link1">
    <inertial>
      <mass value="0.03806502884740436" />
      <origin rpy="0 0 0" xyz="0 0 0" />
      <inertia ixx="0.00028979287111817464" ixy="-8.971989817752046e-19" ixz="-0.0007186296796101484" iyy="0.002082237014513603" iyz="-3.590877595271991e-19" izz="0.0017941228111675988" />
    </inertial>
    <collision name="wrist_left_link1_collision">
      <origin rpy="0 0 0" xyz="0 0 0" />
      <geometry>
        <sphere radius="0.01"/> 
        <!-- TODO -->
        <!-- <mesh filename="package://ros2_control_upper_body/meshes/collisions/wrist_left_link1.stl" scale="0.001 0.001 0.001" /> -->
      </geometry>
    </collision>
    <visual name="wrist_left_link1_visual">
      <origin rpy="0 0 0" xyz="0 0 0" />
      <geometry>
        <sphere radius="0.01"/> 
        <!-- TODO -->
        <!-- <mesh filename="package://ros2_control_upper_body/meshes/visuals/wrist_left_link1.stl" scale="0.001 0.001 0.001" /> -->
      </geometry>
    </visual>
  </link>
  <link name="wrist_left_link2">
    <inertial>
      <mass value="0.002996372533177606" />
      <origin rpy="0 0 0" xyz="0 0 0" />
      <inertia ixx="2.2703814321140076e-05" ixy="-7.034303695085953e-20" ixz="-5.656851705386013e-05" iyy="0.00016380000053594067" iyz="-2.816757244117341e-20" izz="0.00014112045683231935" />
    </inertial>
    <collision name="wrist_left_link2_collision">
      <origin rpy="0 0 0" xyz="0 0 0" />
      <geometry>
        <sphere radius="0.01"/> 
        <!-- TODO -->
        <!-- <mesh filename="package://ros2_control_upper_body/meshes/collisions/wrist_left_link2.stl" scale="0.001 0.001 0.001" /> -->
      </geometry>
    </collision>
    <visual name="wrist_left_link2_visual">
      <origin rpy="0 0 0" xyz="0 0 0" />
      <geometry>
        <sphere radius="0.01"/> 
        <!-- TODO -->
        <!-- <mesh filename="package://ros2_control_upper_body/meshes/visuals/wrist_left_link2.stl" scale="0.001 0.001 0.001" /> -->
      </geometry>
    </visual>
  </link>
  <link name="wrist_right_link1">
    <inertial>
      <mass value="0.03806502884740437" />
      <origin rpy="0 0 0" xyz="0 0 0" />
      <inertia ixx="0.00028979287111819324" ixy="1.061650767297806e-18" ixz="0.0007185410043660903" iyy="0.0020817946848411925" iyz="-4.250072516143178e-19" izz="0.0017936804814951703" />
    </inertial>
    <collision name="wrist_right_link1_collision">
      <origin rpy="0 0 0" xyz="0 0 0" />
      <geometry>
        <sphere radius="0.01"/> 
        <!-- TODO -->  
        <!-- <mesh filename="package://ros2_control_upper_body/meshes/collisions/wrist_right_link1.stl" scale="0.001 0.001 0.001" /> -->
      </geometry>
    </collision>
    <visual name="wrist_right_link1_visual">
      <origin rpy="0 0 0" xyz="0 0 0" />
      <geometry>
        <sphere radius="0.01"/> 
        <!-- TODO -->
        <!-- <mesh filename="package://ros2_control_upper_body/meshes/visuals/wrist_right_link1.stl" scale="0.001 0.001 0.001" /> -->
      </geometry>
    </visual>
  </link>
  <link name="wrist_right_link2">
    <inertial>
      <mass value="0.002996372533177606" />
      <origin rpy="0 0 0" xyz="0 0 0" />
      <inertia ixx="2.2703814321141537e-05" ixy="8.278967789099312e-20" ixz="5.656153678683516e-05" iyy="0.0001637651815821358" iyz="-3.315490243460673e-20" izz="0.000141085637878513" />
    </inertial>
    <collision name="wrist_right_link2_collision">
      <origin rpy="0 0 0" xyz="0 0 0" />
      <geometry>
        <sphere radius="0.01"/> 
        <!-- TODO -->
        <!-- <mesh filename="package://ros2_control_upper_body/meshes/collisions/wrist_right_link2.stl" scale="0.001 0.001 0.001" /> -->
      </geometry>
    </collision>
    <visual name="wrist_right_link2_visual">
      <origin rpy="0 0 0" xyz="0 0 0" />
      <geometry>
        <sphere radius="0.01"/> 
        <!-- TODO -->
        <!-- <mesh filename="package://ros2_control_upper_body/meshes/visuals/wrist_right_link2.stl" scale="0.001 0.001 0.001" /> -->
      </geometry>
    </visual>
  </link>

  <ros2_control name="UpperBody" type="system">
    <hardware>
      <!-- <plugin>{Name_Space}/{Class_Name}</plugin> -->
      <!-- <plugin>ros2_control_kindyn/RobotHardware</plugin> -->
      <plugin>ros2_control_kindyn/UpperBody</plugin>
      <param name="example_param_hw_start_duration_sec">0</param>
      <param name="example_param_hw_stop_duration_sec">3.0</param>
      <param name="example_param_hw_slowdown">100</param>
    </hardware>
    <joint name="shoulder_left_axis0">
      <command_interface name="position">
        <param name="min">{-2*pi}</param>
        <param name="max">{2*pi}</param>
      </command_interface>
      <!-- <command_interface name="velocity">
        <param name="min">-3.15</param>
        <param name="max">3.15</param>
      </command_interface> -->
      <state_interface name="position"/>
      <!-- <state_interface name="velocity"/> -->
    </joint>
    <joint name="shoulder_left_axis1">
      <command_interface name="position">
        <param name="min">{-2*pi}</param>
        <param name="max">{2*pi}</param>
      </command_interface>
      <!-- <command_interface name="velocity">
        <param name="min">-3.15</param>
        <param name="max">3.15</param>
      </command_interface> -->
      <state_interface name="position"/>
      <!-- <state_interface name="velocity"/> -->
    </joint>
    <joint name="shoulder_left_axis2">
      <command_interface name="position">
        <param name="min">{-2*pi}</param>
        <param name="max">{2*pi}</param>
      </command_interface>
      <!-- <command_interface name="velocity">
        <param name="min">-3.15</param>
        <param name="max">3.15</param>
      </command_interface> -->
      <state_interface name="position"/>
      <!-- <state_interface name="velocity"/> -->
    </joint>
    <joint name="elbow_left_axis0">
      <command_interface name="position">
        <param name="min">{-2*pi}</param>
        <param name="max">{2*pi}</param>
      </command_interface>
      <!-- <command_interface name="velocity">
        <param name="min">-3.15</param>
        <param name="max">3.15</param>
      </command_interface> -->
      <state_interface name="position"/>
      <!-- <state_interface name="velocity"/> -->
    </joint>
    <joint name="elbow_left_axis1">
      <command_interface name="position">
        <param name="min">{-2*pi}</param>
        <param name="max">{2*pi}</param>
      </command_interface>
      <!-- <command_interface name="velocity">
        <param name="min">-3.15</param>
        <param name="max">3.15</param>
      </command_interface> -->
      <state_interface name="position"/>
      <!-- <state_interface name="velocity"/> -->
    </joint>
    <joint name="wrist_left_axis0">
      <command_interface name="position">
        <param name="min">{-2*pi}</param>
        <param name="max">{2*pi}</param>
      </command_interface>
      <state_interface name="position"/>
    </joint>
    <joint name="wrist_left_axis1">
      <command_interface name="position">
        <param name="min">{-2*pi}</param>
        <param name="max">{2*pi}</param>
      </command_interface>
      <state_interface name="position"/>
    </joint>
    <joint name="wrist_left_axis2">
      <command_interface name="position">
        <param name="min">{-2*pi}</param>
        <param name="max">{2*pi}</param>
      </command_interface>
      <state_interface name="position"/>
    </joint>
    <joint name="head_axis0">
      <command_interface name="position">
        <param name="min">{-2*pi}</param>
        <param name="max">{2*pi}</param>
      </command_interface>
      <!-- <command_interface name="velocity">
        <param name="min">-3.15</param>
        <param name="max">3.15</param>
      </command_interface> -->
      <state_interface name="position"/>
      <!-- <state_interface name="velocity"/> -->
    </joint>
    <joint name="head_axis1">
      <command_interface name="position">
        <param name="min">{-2*pi}</param>
        <param name="max">{2*pi}</param>
      </command_interface>
      <!-- <command_interface name="velocity">
        <param name="min">-3.15</param>
        <param name="max">3.15</param>
      </command_interface> -->
      <state_interface name="position"/>
      <!-- <state_interface name="velocity"/> -->
    </joint>
    <joint name="head_axis2">
      <command_interface name="position">
        <param name="min">{-2*pi}</param>
        <param name="max">{2*pi}</param>
      </command_interface>
      <!-- <command_interface name="velocity">
        <param name="min">-3.15</param>
        <param name="max">3.15</param>
      </command_interface> -->
      <state_interface name="position"/>
      <!-- <state_interface name="velocity"/> -->
    </joint>
    <joint name="shoulder_right_axis0">
      <command_interface name="position">
        <param name="min">{-2*pi}</param>
        <param name="max">{2*pi}</param>
      </command_interface>
      <!-- <command_interface name="velocity">
        <param name="min">-3.15</param>
        <param name="max">3.15</param>
      </command_interface> -->
      <state_interface name="position"/>
      <!-- <state_interface name="velocity"/> -->
    </joint>
    <joint name="shoulder_right_axis1">
      <command_interface name="position">
        <param name="min">{-2*pi}</param>
        <param name="max">{2*pi}</param>
      </command_interface>
      <!-- <command_interface name="velocity">
        <param name="min">-3.15</param>
        <param name="max">3.15</param>
      </command_interface> -->
      <state_interface name="position"/>
      <!-- <state_interface name="velocity"/> -->
    </joint>
    <joint name="shoulder_right_axis2">
      <command_interface name="position">
        <param name="min">{-2*pi}</param>
        <param name="max">{2*pi}</param>
      </command_interface>
      <!-- <command_interface name="velocity">
        <param name="min">-3.15</param>
        <param name="max">3.15</param>
      </command_interface> -->
      <state_interface name="position"/>
      <!-- <state_interface name="velocity"/> -->
    </joint>
    <joint name="elbow_right_axis0">
      <command_interface name="position">
        <param name="min">{-2*pi}</param>
        <param name="max">{2*pi}</param>
      </command_interface>
      <!-- <command_interface name="velocity">
        <param name="min">-3.15</param>
        <param name="max">3.15</param>
      </command_interface> -->
      <state_interface name="position"/>
      <!-- <state_interface name="velocity"/> -->
    </joint>
    <joint name="elbow_right_axis1">
      <command_interface name="position">
        <param name="min">{-2*pi}</param>
        <param name="max">{2*pi}</param>
      </command_interface>
      <!-- <command_interface name="velocity">
        <param name="min">-3.15</param>
        <param name="max">3.15</param>
      </command_interface> -->
      <state_interface name="position"/>
      <!-- <state_interface name="velocity"/> -->
    </joint>
    <joint name="wrist_right_axis0">
      <command_interface name="position">
        <param name="min">{-2*pi}</param>
        <param name="max">{2*pi}</param>
      </command_interface>
      <state_interface name="position"/>
    </joint>
    <joint name="wrist_right_axis1">
      <command_interface name="position">
        <param name="min">{-2*pi}</param>
        <param name="max">{2*pi}</param>
      </command_interface>
      <state_interface name="position"/>
    </joint>
    <joint name="wrist_right_axis2">
      <command_interface name="position">
        <param name="min">{-2*pi}</param>
        <param name="max">{2*pi}</param>
      </command_interface>
      <state_interface name="position"/>
    </joint>
  </ros2_control>
</robot>
