<sdf version="1.6">
	<model name="head_testbed">
		<link name="head">
			<self_collide>false</self_collide>
			<pose frame="">2.4611174625077045e-05 -0.0016286099831791623 0.19372598298431493 0.0 -0.0 0.0</pose>
			<inertial>
				<pose frame="">0.0 0.0 0.0 0 0 0</pose>
				<mass>2.6664081866441176</mass>
				<inertia>
					<ixx>0.13857408469680862</ixx>
					<ixy>1.9616737535562442e-05</ixy>
					<ixz>-3.920317094358494e-05</ixz>
					<iyy>0.13933836843914202</iyy>
					<iyz>-0.002684152071919728</iyz>
					<izz>0.03361440293738789</izz>
				</inertia>
			</inertial>
			<collision name="head_collision">
				<geometry>
					<mesh>
						<uri>model://head_testbed/meshes/collisions/head.stl</uri>
						<scale>0.001 0.001 0.001</scale>
					</mesh>
				</geometry>
			</collision>
			<visual name="head_visual">
				<geometry>
					<mesh>
						<uri>model://head_testbed/meshes/visuals/head.stl</uri>
						<scale>0.001 0.001 0.001</scale>
					</mesh>
				</geometry>
			</visual>
		</link>
		<link name="base">
			<self_collide>false</self_collide>
			<pose frame="">-0.0006080417979969455 0.0023707160382271594 -0.05182768598878378 0.0 -0.0 0.0</pose>
			<inertial>
				<pose frame="">0.0 0.0 0.0 0 0 0</pose>
				<mass>6.996626773526851</mass>
				<inertia>
					<ixx>0.02900957380282074</ixx>
					<ixy>-1.2359125747757903e-06</ixy>
					<ixz>-0.00024807236774458875</ixz>
					<iyy>0.0388014394340287</iyy>
					<iyz>0.0009804440070563959</iyz>
					<izz>0.015022912894190108</izz>
				</inertia>
			</inertial>
			<collision name="base_collision">
				<geometry>
					<mesh>
						<uri>model://head_testbed/meshes/collisions/base.stl</uri>
						<scale>0.001 0.001 0.001</scale>
					</mesh>
				</geometry>
			</collision>
			<visual name="base_visual">
				<geometry>
					<mesh>
						<uri>model://head_testbed/meshes/visuals/base.stl</uri>
						<scale>0.001 0.001 0.001</scale>
					</mesh>
				</geometry>
			</visual>
		</link>
		<link name="head_link1">
			<self_collide>false</self_collide>
			<pose frame="">4.557263000984424e-19 -1.7659394128814645e-18 0.026000000000000047 0.0 -0.0 0.0</pose>
			<inertial>
				<pose frame="">0.0 0.0 0.0 0 0 0</pose>
				<mass>0.03806502884740436</mass>
				<inertia>
					<ixx>2.741062727301597e-05</ixx>
					<ixy>1.9515639104739082e-22</ixy>
					<ixz>-2.2551405187698495e-21</ixz>
					<iyy>2.741062727301597e-05</iyy>
					<iyz>8.673617379884036e-23</iyz>
					<izz>1.6786677721705307e-06</izz>
				</inertia>
			</inertial>
			<collision name="head_link1_collision">
				<geometry>
					<mesh>
						<uri>model://head_testbed/meshes/collisions/head_link1.stl</uri>
						<scale>0.001 0.001 0.001</scale>
					</mesh>
				</geometry>
			</collision>
			<visual name="head_link1_visual">
				<geometry>
					<mesh>
						<uri>model://head_testbed/meshes/visuals/head_link1.stl</uri>
						<scale>0.001 0.001 0.001</scale>
					</mesh>
				</geometry>
			</visual>
		</link>
		<link name="head_link2">
			<self_collide>false</self_collide>
			<pose frame="">3.6357506646816577e-19 -2.9851655039434398e-18 0.026000000000000054 0.0 -0.0 0.0</pose>
			<inertial>
				<pose frame="">0.0 0.0 0.0 0 0 0</pose>
				<mass>0.0029963725331776064</mass>
				<inertia>
					<ixx>2.0498184499468094e-06</ixx>
					<ixy>8.851426536171665e-24</ixy>
					<ixz>-6.618143533199126e-23</ixz>
					<iyy>2.0498184499468085e-06</iyy>
					<iyz>2.656295322589486e-22</iyz>
					<izz>2.4270617518738147e-08</izz>
				</inertia>
			</inertial>
			<collision name="head_link2_collision">
				<geometry>
					<mesh>
						<uri>model://head_testbed/meshes/collisions/head_link2.stl</uri>
						<scale>0.001 0.001 0.001</scale>
					</mesh>
				</geometry>
			</collision>
			<visual name="head_link2_visual">
				<geometry>
					<mesh>
						<uri>model://head_testbed/meshes/visuals/head_link2.stl</uri>
						<scale>0.001 0.001 0.001</scale>
					</mesh>
				</geometry>
			</visual>
		</link>
		<joint name="head_axis0" type="revolute">
			<parent>base</parent>
			<child>head_link1</child>
			<pose frame="">6.544967245267135e-19 -1.769508802125596e-19 4.440892098500626e-18 0 0 0</pose>
			<axis>
				<xyz>1.0 -5.551115123125785e-17 -3.0814879110195774e-33</xyz>
				<limit>
					<lower>-3.141592653589793</lower>
					<upper>3.141592653589793</upper>
				</limit>
				<use_parent_model_frame>0</use_parent_model_frame>
			</axis>
		</joint>
		<joint name="head_axis1" type="revolute">
			<parent>head_link1</parent>
			<child>head_link2</child>
			<pose frame="">7.466479581569901e-19 1.0422752108494158e-18 -4.440892098500626e-18 0 0 0</pose>
			<axis>
				<xyz>5.551115123125785e-17 1.0 1.4643661852621273e-18</xyz>
				<limit>
					<lower>-3.141592653589793</lower>
					<upper>3.141592653589793</upper>
				</limit>
				<use_parent_model_frame>0</use_parent_model_frame>
			</axis>
		</joint>
		<joint name="head_axis2" type="revolute">
			<parent>head_link2</parent>
			<child>head</child>
			<pose frame="">-2.4611174625075937e-05 0.0016286099831791603 -0.16772598298431488 0 0 0</pose>
			<axis>
				<xyz>0.0 -1.4643661852621273e-18 1.0</xyz>
				<limit>
					<lower>-3.141592653589793</lower>
					<upper>3.141592653589793</upper>
				</limit>
				<use_parent_model_frame>0</use_parent_model_frame>
			</axis>
		</joint>
		<plugin filename="libcardsflow_gazebo_plugin.so" name="cardsflow_gazebo_plugin" />
	</model>
</sdf>