<robot name="head_testbed">
  <joint name="head_axis0" type="revolute">
    <parent link="base" />
    <child link="head_link1" />
    <origin rpy="0  0  0" xyz="0     0     0.026" />
    <axis xyz="1  0  0" />
    <limit effort="0.0" lower="-3.14159265359" upper="3.14159265359" velocity="0.0" />
  </joint>
  <joint name="head_axis1" type="revolute">
    <parent link="head_link1" />
    <child link="head_link2" />
    <origin rpy="0  0  0" xyz="0  0  0" />
    <axis xyz="0  1  0" />
    <limit effort="0.0" lower="-3.14159265359" upper="3.14159265359" velocity="0.0" />
  </joint>
  <joint name="head_axis2" type="revolute">
    <parent link="head_link2" />
    <child link="head" />
    <origin rpy="0  0  0" xyz="0  0  0" />
    <axis xyz="0  0  1" />
    <limit effort="0.0" lower="-3.14159265359" upper="3.14159265359" velocity="0.0" />
  </joint>
  <link name="head">
    <inertial>
      <mass value="2.6664081866441176" />
      <origin rpy="0  0  0" xyz="2.00000000e-05  -1.62000000e-03   1.67720000e-01" />
      <inertia ixx="0.13857408469680862" ixy="1.9616737535562442e-05" ixz="-3.920317094358494e-05" iyy="0.13933836843914202" iyz="-0.002684152071919728" izz="0.03361440293738789" />
    </inertial>
    <collision name="head_collision">
      <origin rpy="0  0  0" xyz="2.00000000e-05  -1.62000000e-03   1.67720000e-01" />
      <geometry>
        <mesh filename="package://robots/head_testbed/meshes/collisions/head.stl" scale="0.001 0.001 0.001" />
      </geometry>
    </collision>
    <visual name="head_visual">
      <origin rpy="0  0  0" xyz="2.00000000e-05  -1.62000000e-03   1.67720000e-01" />
      <geometry>
        <mesh filename="package://robots/head_testbed/meshes/visuals/head.stl" scale="0.001 0.001 0.001" />
      </geometry>
    </visual>
  </link>
  <link name="base">
    <inertial>
      <mass value="6.996626773526851" />
      <origin rpy="0  0  0" xyz="-0.0006   0.00237 -0.05182" />
      <inertia ixx="0.02900957380282074" ixy="-1.2359125747757903e-06" ixz="-0.00024807236774458875" iyy="0.0388014394340287" iyz="0.0009804440070563959" izz="0.015022912894190108" />
    </inertial>
    <collision name="base_collision">
      <origin rpy="0  0  0" xyz="-0.0006   0.00237 -0.05182" />
      <geometry>
        <mesh filename="package://robots/head_testbed/meshes/collisions/base.stl" scale="0.001 0.001 0.001" />
      </geometry>
    </collision>
    <visual name="base_visual">
      <origin rpy="0  0  0" xyz="-0.0006   0.00237 -0.05182" />
      <geometry>
        <mesh filename="package://robots/head_testbed/meshes/visuals/base.stl" scale="0.001 0.001 0.001" />
      </geometry>
    </visual>
  </link>
  <link name="head_link1">
    <inertial>
      <mass value="0.03806502884740436" />
      <origin rpy="0  0  0" xyz="0  0  0" />
      <inertia ixx="2.741062727301597e-05" ixy="1.9515639104739082e-22" ixz="-2.2551405187698495e-21" iyy="2.741062727301597e-05" iyz="8.673617379884036e-23" izz="1.6786677721705307e-06" />
    </inertial>
    <collision name="head_link1_collision">
      <origin rpy="0  0  0" xyz="0  0  0" />
      <geometry>
        <mesh filename="package://robots/head_testbed/meshes/collisions/head_link1.stl" scale="0.001 0.001 0.001" />
      </geometry>
    </collision>
    <visual name="head_link1_visual">
      <origin rpy="0  0  0" xyz="0  0  0" />
      <geometry>
        <mesh filename="package://robots/head_testbed/meshes/visuals/head_link1.stl" scale="0.001 0.001 0.001" />
      </geometry>
    </visual>
  </link>
  <link name="head_link2">
    <inertial>
      <mass value="0.0029963725331776064" />
      <origin rpy="0  0  0" xyz="0  0  0" />
      <inertia ixx="2.0498184499468094e-06" ixy="8.851426536171665e-24" ixz="-6.618143533199126e-23" iyy="2.0498184499468085e-06" iyz="2.656295322589486e-22" izz="2.4270617518738147e-08" />
    </inertial>
    <collision name="head_link2_collision">
      <origin rpy="0  0  0" xyz="0  0  0" />
      <geometry>
        <mesh filename="package://robots/head_testbed/meshes/collisions/head_link2.stl" scale="0.001 0.001 0.001" />
      </geometry>
    </collision>
    <visual name="head_link2_visual">
      <origin rpy="0  0  0" xyz="0  0  0" />
      <geometry>
        <mesh filename="package://robots/head_testbed/meshes/visuals/head_link2.stl" scale="0.001 0.001 0.001" />
      </geometry>
    </visual>
  </link>
</robot>