<?xml version="1.0" ?>
<sdf version="1.6">
	<model name="wrist_testbed">
		<link name="arm_right_lower">
			<self_collide>false</self_collide>
			<pose frame="">-0.18894083144631144 6.66924034808675e-05 0.08299649413848707 0.0 -0.0 0.0</pose>
			<inertial>
				<pose frame="">0.0 0.0 0.0 0 0 0</pose>
				<mass>1.2616679305449068</mass>
				<inertia>
					<ixx>0.01023128335694641</ixx>
					<ixy>1.3435930962272603e-05</ixy>
					<ixz>0.022680817605867543</ixz>
					<iyy>0.065089794225033</iyy>
					<iyz>-7.3637313618544225e-06</iyz>
					<izz>0.05596626358986321</izz>
				</inertia>
			</inertial>
			<collision name="arm_right_lower_collision">
				<geometry>
					<mesh>
						<uri>model://wrist_testbed/meshes/CAD/arm_right_lower.stl</uri>
						<scale>0.001 0.001 0.001</scale>
					</mesh>
				</geometry>
			</collision>
			<visual name="arm_right_lower_visual">
				<geometry>
					<mesh>
						<uri>model://wrist_testbed/meshes/CAD/arm_right_lower.stl</uri>
						<scale>0.001 0.001 0.001</scale>
					</mesh>
				</geometry>
			</visual>
		</link>
		<link name="hand_right">
			<self_collide>false</self_collide>
			<pose frame="">-0.00023417295336083173 6.510381395842973e-05 0.09205924941382375 0.0 -0.0 0.0</pose>
			<inertial>
				<pose frame="">0.0 0.0 0.0 0 0 0</pose>
				<mass>1.1047000476904287</mass>
				<inertia>
					<ixx>0.010140303095379107</ixx>
					<ixy>-3.191495137226376e-06</ixy>
					<ixz>3.0343031201385687e-05</ixz>
					<iyy>0.010138809698272796</iyy>
					<iyz>-7.337182910598767e-06</iyz>
					<izz>0.0010421942131185154</izz>
				</inertia>
			</inertial>
			<collision name="hand_right_collision">
				<geometry>
					<mesh>
						<uri>model://wrist_testbed/meshes/CAD/hand_right.stl</uri>
						<scale>0.001 0.001 0.001</scale>
					</mesh>
				</geometry>
			</collision>
			<visual name="hand_right_visual">
				<geometry>
					<mesh>
						<uri>model://wrist_testbed/meshes/CAD/hand_right.stl</uri>
						<scale>0.001 0.001 0.001</scale>
					</mesh>
				</geometry>
			</visual>
		</link>
		<link name="sphere_link1">
			<self_collide>false</self_collide>
			<pose frame="">-6.095339263816667e-17 1.2532473252707166e-18 0.03799999999999997 0.0 -0.0 0.0</pose>
			<inertial>
				<pose frame="">0.0 0.0 0.0 0 0 0</pose>
				<mass>0.03806502884740436</mass>
				<inertia>
					<ixx>5.664456942782235e-05</ixx>
					<ixy>2.168404344971009e-22</ixy>
					<ixz>8.647596527744384e-20</ixz>
					<iyy>5.664456942782236e-05</iyy>
					<iyz>-3.9031278209478164e-21</iyz>
					<izz>1.6786677721705307e-06</izz>
				</inertia>
			</inertial>
			<collision name="sphere_link1_collision">
				<geometry>
					<mesh>
						<uri>model://wrist_testbed/meshes/CAD/sphere_link1.stl</uri>
						<scale>0.001 0.001 0.001</scale>
					</mesh>
				</geometry>
			</collision>
			<visual name="sphere_link1_visual">
				<geometry>
					<mesh>
						<uri>model://wrist_testbed/meshes/CAD/sphere_link1.stl</uri>
						<scale>0.001 0.001 0.001</scale>
					</mesh>
				</geometry>
			</visual>
		</link>
		<link name="sphere_link2">
			<self_collide>false</self_collide>
			<pose frame="">-6.235312389929044e-17 -4.522978036277939e-19 0.037999999999999964 0.0 -0.0 0.0</pose>
			<inertial>
				<pose frame="">0.0 0.0 0.0 0 0 0</pose>
				<mass>0.0029963725331776064</mass>
				<inertia>
					<ixx>4.351032555427194e-06</ixx>
					<ixy>8.851426536171483e-24</ixy>
					<ixz>7.048731390235643e-21</ixz>
					<iyy>4.351032555427193e-06</iyy>
					<iyz>9.757819552369541e-23</iyz>
					<izz>2.4270617518738147e-08</izz>
				</inertia>
			</inertial>
			<collision name="sphere_link2_collision">
				<geometry>
					<mesh>
						<uri>model://wrist_testbed/meshes/CAD/sphere_link2.stl</uri>
						<scale>0.001 0.001 0.001</scale>
					</mesh>
				</geometry>
			</collision>
			<visual name="sphere_link2_visual">
				<geometry>
					<mesh>
						<uri>model://wrist_testbed/meshes/CAD/sphere_link2.stl</uri>
						<scale>0.001 0.001 0.001</scale>
					</mesh>
				</geometry>
			</visual>
		</link>
		<joint name="sphere_axis0" type="revolute">
			<parent>arm_right_lower</parent>
			<child>sphere_link1</child>
			<pose frame="">-1.219096740842095e-18 -1.2532473252596094e-18 0.0 0 0 0</pose>
			<axis>
				<xyz>1.0 -4.548984898884431e-28 -2.4308653429145085e-62</xyz>
				<limit>
					<lower>-3.141592653589793</lower>
					<upper>3.141592653589793</upper>
				</limit>
				<use_parent_model_frame>0</use_parent_model_frame>
			</axis>
		</joint>
		<joint name="sphere_axis1" type="revolute">
			<parent>sphere_link1</parent>
			<child>sphere_link2</child>
			<pose frame="">1.8063452028167217e-19 4.52297803638901e-19 8.881784197001253e-18 0 0 0</pose>
			<axis>
				<xyz>5.548557947460961e-28 1.0 1.2289325959195016e-28</xyz>
				<limit>
					<lower>-3.141592653589793</lower>
					<upper>3.141592653589793</upper>
				</limit>
				<use_parent_model_frame>0</use_parent_model_frame>
			</axis>
		</joint>
		<joint name="sphere_axis2" type="revolute">
			<parent>sphere_link2</parent>
			<child>hand_right</child>
			<pose frame="">0.00023417295336076955 -6.510381395842973e-05 -0.05405924941382377 0 0 0</pose>
			<axis>
				<xyz>-6.599952185900785e-56 -1.2289325959195016e-28 1.0</xyz>
				<limit>
					<lower>-3.141592653589793</lower>
					<upper>3.141592653589793</upper>
				</limit>
				<use_parent_model_frame>0</use_parent_model_frame>
			</axis>
		</joint>
		<plugin filename="libcardsflow_gazebo_plugin.so" name="cardsflow_gazebo_plugin"/>
	</model>
</sdf>
